Workbook

Sheet 日超8H
A3: 计数项:工号 | C3: 是否日超8H | G3: 计数项:工号 | J3: 是否日超8H
A4: 三级部门 | B4: 四级部门 | C4: 是 | D4: 否 | E4: 总计 | G4: 三级部门 | H4: 四级部门 | I4: 辅助 | J4: 是 | K4: 否 | L4: 总计
A5: AD 行政部 | C5: 10 | D5: 8 | E5: 18 | G5: AD 行政部 | I5: =G5&""&H5 -> AD 行政部 | J5: 10 | K5: 8 | L5: 18
A6: AS 审计监察部 | C6: 1 | D6: 1 | E6: 2 | G6: AS 审计监察部 | I6: =G6&""&H6 -> AS 审计监察部 | J6: 1 | K6: 1 | L6: 2
A7: BD 本地客户部 | D7: 17 | E7: 17 | G7: BD 本地客户部 | I7: =G7&""&H7 -> BD 本地客户部 | K7: 17 | L7: 17
A8: BM 品牌市场部 | C8: 2 | D8: 4 | E8: 6 | G8: BM 品牌市场部 | I8: =G8&""&H8 -> BM 品牌市场部 | J8: 2 | K8: 4 | L8: 6
A9: CM 运力管理部 | C9: 5 | D9: 7 | E9: 12 | G9: CM 运力管理部 | I9: =G9&""&H9 -> CM 运力管理部 | J9: 5 | K9: 7 | L9: 12
A10: CS 客户服务部 | C10: 6 | D10: 1 | E10: 7 | G10: CS 客户服务部 | I10: =G10&""&H10 -> CS 客户服务部 | J10: 6 | K10: 1 | L10: 7
A11: DO 数字运营部 | C11: 3 | D11: 12 | E11: 15 | G11: DO 数字运营部 | I11: =G11&""&H11 -> DO 数字运营部 | J11: 3 | K11: 12 | L11: 15
A12: FL 佛州大区 | D12: 1 | E12: 1 | G12: FL 佛州大区 | I12: =G12&""&H12 -> FL 佛州大区 | K12: 1 | L12: 1
A13: FL 佛州大区 | B13: FTM01 | D13: 3 | E13: 3 | G13: FL 佛州大区 | H13: FTM01 | I13: =G13&""&H13 -> FL 佛州大区FTM01 | K13: 3 | L13: 3
A14: FL 佛州大区 | B14: MCO.H | C14: 15 | D14: 13 | E14: 28 | G14: FL 佛州大区 | H14: MCO.H | I14: =G14&""&H14 -> FL 佛州大区MCO.H | J14: 15 | K14: 13 | L14: 28
A15: FL 佛州大区 | B15: MCO01 | C15: 2 | E15: 2 | G15: FL 佛州大区 | H15: MCO01 | I15: =G15&""&H15 -> FL 佛州大区MCO01 | J15: 2 | L15: 2
A16: FL 佛州大区 | B16: MF 中佛片区 | C16: 3 | D16: 4 | E16: 7 | G16: FL 佛州大区 | H16: MF 中佛片区 | I16: =G16&""&H16 -> FL 佛州大区MF 中佛片区 | J16: 3 | K16: 4 | L16: 7
A17: FL 佛州大区 | B17: MIA.H | C17: 17 | D17: 17 | E17: 34 | G17: FL 佛州大区 | H17: MIA.H | I17: =G17&""&H17 -> FL 佛州大区MIA.H | J17: 17 | K17: 17 | L17: 34
A18: FL 佛州大区 | B18: MIA01 | C18: 2 | D18: 1 | E18: 3 | G18: FL 佛州大区 | H18: MIA01 | I18: =G18&""&H18 -> FL 佛州大区MIA01 | J18: 2 | K18: 1 | L18: 3
A19: FL 佛州大区 | B19: NF 北佛片区 | C19: 1 | D19: 6 | E19: 7 | G19: FL 佛州大区 | H19: NF 北佛片区 | I19: =G19&""&H19 -> FL 佛州大区NF 北佛片区 | J19: 1 | K19: 6 | L19: 7
A20: FL 佛州大区 | B20: OCF01 | C20: 1 | E20: 1 | G20: FL 佛州大区 | H20: OCF01 | I20: =G20&""&H20 -> FL 佛州大区OCF01 | J20: 1 | L20: 1
A21: FL 佛州大区 | B21: SF 南佛片区 | C21: 4 | D21: 6 | E21: 10 | G21: FL 佛州大区 | H21: SF 南佛片区 | I21: =G21&""&H21 -> FL 佛州大区SF 南佛片区 | J21: 4 | K21: 6 | L21: 10
A22: FL 佛州大区 | B22: SRQ01 | C22: 1 | E22: 1 | G22: FL 佛州大区 | H22: SRQ01 | I22: =G22&""&H22 -> FL 佛州大区SRQ01 | J22: 1 | L22: 1
A23: FL 佛州大区 | B23: TPA01 | D23: 2 | E23: 2 | G23: FL 佛州大区 | H23: TPA01 | I23: =G23&""&H23 -> FL 佛州大区TPA01 | K23: 2 | L23: 2
A24: FL 佛州大区 | B24: WF 西佛片区 | C24: 1 | D24: 5 | E24: 6 | G24: FL 佛州大区 | H24: WF 西佛片区 | I24: =G24&""&H24 -> FL 佛州大区WF 西佛片区 | J24: 1 | K24: 5 | L24: 6
A25: FL 佛州大区 | B25: WPB01 | D25: 1 | E25: 1 | G25: FL 佛州大区 | H25: WPB01 | I25: =G25&""&H25 -> FL 佛州大区WPB01 | K25: 1 | L25: 1
A26: FL 佛州大区 | B26: 运营支持部 | C26: 3 | D26: 1 | E26: 4 | G26: FL 佛州大区 | H26: 运营支持部 | I26: =G26&""&H26 -> FL 佛州大区运营支持部 | J26: 3 | K26: 1 | L26: 4
A27: FL 佛州大区 汇总 | C27: 50 | D27: 60 | E27: 110 | G27: FL 佛州大区 汇总 | I27: =G27&""&H27 -> FL 佛州大区 汇总 | J27: 50 | K27: 60 | L27: 110
A28: GL 大湖大区 | C28: 1 | D28: 1 | E28: 2 | G28: GL 大湖大区 | I28: =G28&""&H28 -> GL 大湖大区 | J28: 1 | K28: 1 | L28: 2
A29: GL 大湖大区 | B29: CLE01 | C29: 1 | E29: 1 | G29: GL 大湖大区 | H29: CLE01 | I29: =G29&""&H29 -> GL 大湖大区CLE01 | J29: 1 | L29: 1
A30: GL 大湖大区 | B30: CM 中西部中心片区 | C30: 2 | D30: 4 | E30: 6 | G30: GL 大湖大区 | H30: CM 中西部中心片区 | I30: =G30&""&H30 -> GL 大湖大区CM 中西部中心片区 | J30: 2 | K30: 4 | L30: 6
A31: GL 大湖大区 | B31: CMH01 | D31: 1 | E31: 1 | G31: GL 大湖大区 | H31: CMH01 | I31: =G31&""&H31 -> GL 大湖大区CMH01 | K31: 1 | L31: 1
A32: GL 大湖大区 | B32: CVG.H | C32: 1 | D32: 1 | E32: 2 | G32: GL 大湖大区 | H32: CVG.H | I32: =G32&""&H32 -> GL 大湖大区CVG.H | J32: 1 | K32: 1 | L32: 2
A33: GL 大湖大区 | B33: EG 东大湖片区 | C33: 1 | D33: 4 | E33: 5 | G33: GL 大湖大区 | H33: EG 东大湖片区 | I33: =G33&""&H33 -> GL 大湖大区EG 东大湖片区 | J33: 1 | K33: 4 | L33: 5
A34: GL 大湖大区 | B34: IND01 | C34: 1 | D34: 2 | E34: 3 | G34: GL 大湖大区 | H34: IND01 | I34: =G34&""&H34 -> GL 大湖大区IND01 | J34: 1 | K34: 2 | L34: 3
A35: GL 大湖大区 | B35: MCI01 | C35: 1 | D35: 1 | E35: 2 | G35: GL 大湖大区 | H35: MCI01 | I35: =G35&""&H35 -> GL 大湖大区MCI01 | J35: 1 | K35: 1 | L35: 2
A36: GL 大湖大区 | B36: MKE01 | D36: 2 | E36: 2 | G36: GL 大湖大区 | H36: MKE01 | I36: =G36&""&H36 -> GL 大湖大区MKE01 | K36: 2 | L36: 2
A37: GL 大湖大区 | B37: NM 中西部北片区 | C37: 2 | D37: 4 | E37: 6 | G37: GL 大湖大区 | H37: NM 中西部北片区 | I37: =G37&""&H37 -> GL 大湖大区NM 中西部北片区 | J37: 2 | K37: 4 | L37: 6
A38: GL 大湖大区 | B38: ORD.H | C38: 15 | D38: 14 | E38: 29 | G38: GL 大湖大区 | H38: ORD.H | I38: =G38&""&H38 -> GL 大湖大区ORD.H | J38: 15 | K38: 14 | L38: 29
A39: GL 大湖大区 | B39: ORD01 | D39: 2 | E39: 2 | G39: GL 大湖大区 | H39: ORD01 | I39: =G39&""&H39 -> GL 大湖大区ORD01 | K39: 2 | L39: 2
A40: GL 大湖大区 | B40: WG 西大湖片区 | C40: 3 | D40: 7 | E40: 10 | G40: GL 大湖大区 | H40: WG 西大湖片区 | I40: =G40&""&H40 -> GL 大湖大区WG 西大湖片区 | J40: 3 | K40: 7 | L40: 10
A41: GL 大湖大区 | B41: 车辆管理部 | D41: 1 | E41: 1 | G41: GL 大湖大区 | H41: 车辆管理部 | I41: =G41&""&H41 -> GL 大湖大区车辆管理部 | K41: 1 | L41: 1
A42: GL 大湖大区 | B42: 揽收部 | C42: 4 | D42: 1 | E42: 5 | G42: GL 大湖大区 | H42: 揽收部 | I42: =G42&""&H42 -> GL 大湖大区揽收部 | J42: 4 | K42: 1 | L42: 5
...

Sheet 是否排班
A3: 计数项:工号 | C3: 是否排班 | G3: 计数项:工号 | J3: 是否排班
A4: 三级部门 | B4: 四级部门 | C4: 是 | D4: 否 | E4: 总计 | G4: 三级部门 | H4: 四级部门 | I4: 辅助 | J4: 是 | K4: 否 | L4: 总计 | M4: 排班率
A5: AD 行政部 | C5: 18 | E5: 18 | G5: AD 行政部 | I5: =G5&""&H5 -> AD 行政部 | J5: 18 | L5: 18 | M5: =J5/L5 -> 1
A6: AS 审计监察部 | C6: 2 | E6: 2 | G6: AS 审计监察部 | I6: =G6&""&H6 -> AS 审计监察部 | J6: 2 | L6: 2 | M6: =J6/L6 -> 1
A7: BD 本地客户部 | C7: 17 | E7: 17 | G7: BD 本地客户部 | I7: =G7&""&H7 -> BD 本地客户部 | J7: 17 | L7: 17 | M7: =J7/L7 -> 1
A8: BM 品牌市场部 | C8: 6 | E8: 6 | G8: BM 品牌市场部 | I8: =G8&""&H8 -> BM 品牌市场部 | J8: 6 | L8: 6 | M8: =J8/L8 -> 1
A9: CM 运力管理部 | C9: 12 | E9: 12 | G9: CM 运力管理部 | I9: =G9&""&H9 -> CM 运力管理部 | J9: 12 | L9: 12 | M9: =J9/L9 -> 1
A10: CS 客户服务部 | C10: 7 | E10: 7 | G10: CS 客户服务部 | I10: =G10&""&H10 -> CS 客户服务部 | J10: 7 | L10: 7 | M10: =J10/L10 -> 1
A11: DO 数字运营部 | C11: 15 | E11: 15 | G11: DO 数字运营部 | I11: =G11&""&H11 -> DO 数字运营部 | J11: 15 | L11: 15 | M11: =J11/L11 -> 1
A12: FL 佛州大区 | C12: 1 | E12: 1 | G12: FL 佛州大区 | I12: =G12&""&H12 -> FL 佛州大区 | J12: 1 | L12: 1 | M12: =J12/L12 -> 1
A13: FL 佛州大区 | B13: FTM01 | C13: 3 | E13: 3 | G13: FL 佛州大区 | H13: FTM01 | I13: =G13&""&H13 -> FL 佛州大区FTM01 | J13: 3 | L13: 3 | M13: =J13/L13 -> 1
A14: FL 佛州大区 | B14: MCO.H | C14: 28 | E14: 28 | G14: FL 佛州大区 | H14: MCO.H | I14: =G14&""&H14 -> FL 佛州大区MCO.H | J14: 28 | L14: 28 | M14: =J14/L14 -> 1
A15: FL 佛州大区 | B15: MCO01 | C15: 2 | E15: 2 | G15: FL 佛州大区 | H15: MCO01 | I15: =G15&""&H15 -> FL 佛州大区MCO01 | J15: 2 | L15: 2 | M15: =J15/L15 -> 1
A16: FL 佛州大区 | B16: MF 中佛片区 | C16: 7 | E16: 7 | G16: FL 佛州大区 | H16: MF 中佛片区 | I16: =G16&""&H16 -> FL 佛州大区MF 中佛片区 | J16: 7 | L16: 7 | M16: =J16/L16 -> 1
A17: FL 佛州大区 | B17: MIA.H | C17: 33 | D17: 1 | E17: 34 | G17: FL 佛州大区 | H17: MIA.H | I17: =G17&""&H17 -> FL 佛州大区MIA.H | J17: 33 | K17: 1 | L17: 34 | M17: =J17/L17 -> 0.97058824
A18: FL 佛州大区 | B18: MIA01 | C18: 3 | E18: 3 | G18: FL 佛州大区 | H18: MIA01 | I18: =G18&""&H18 -> FL 佛州大区MIA01 | J18: 3 | L18: 3 | M18: =J18/L18 -> 1
A19: FL 佛州大区 | B19: NF 北佛片区 | C19: 7 | E19: 7 | G19: FL 佛州大区 | H19: NF 北佛片区 | I19: =G19&""&H19 -> FL 佛州大区NF 北佛片区 | J19: 7 | L19: 7 | M19: =J19/L19 -> 1
A20: FL 佛州大区 | B20: OCF01 | C20: 1 | E20: 1 | G20: FL 佛州大区 | H20: OCF01 | I20: =G20&""&H20 -> FL 佛州大区OCF01 | J20: 1 | L20: 1 | M20: =J20/L20 -> 1
A21: FL 佛州大区 | B21: SF 南佛片区 | C21: 9 | D21: 1 | E21: 10 | G21: FL 佛州大区 | H21: SF 南佛片区 | I21: =G21&""&H21 -> FL 佛州大区SF 南佛片区 | J21: 9 | K21: 1 | L21: 10 | M21: =J21/L21 -> 0.9
A22: FL 佛州大区 | B22: SRQ01 | C22: 1 | E22: 1 | G22: FL 佛州大区 | H22: SRQ01 | I22: =G22&""&H22 -> FL 佛州大区SRQ01 | J22: 1 | L22: 1 | M22: =J22/L22 -> 1
A23: FL 佛州大区 | B23: TPA01 | C23: 2 | E23: 2 | G23: FL 佛州大区 | H23: TPA01 | I23: =G23&""&H23 -> FL 佛州大区TPA01 | J23: 2 | L23: 2 | M23: =J23/L23 -> 1
A24: FL 佛州大区 | B24: WF 西佛片区 | C24: 6 | E24: 6 | G24: FL 佛州大区 | H24: WF 西佛片区 | I24: =G24&""&H24 -> FL 佛州大区WF 西佛片区 | J24: 6 | L24: 6 | M24: =J24/L24 -> 1
A25: FL 佛州大区 | B25: WPB01 | C25: 1 | E25: 1 | G25: FL 佛州大区 | H25: WPB01 | I25: =G25&""&H25 -> FL 佛州大区WPB01 | J25: 1 | L25: 1 | M25: =J25/L25 -> 1
A26: FL 佛州大区 | B26: 运营支持部 | C26: 4 | E26: 4 | G26: FL 佛州大区 | H26: 运营支持部 | I26: =G26&""&H26 -> FL 佛州大区运营支持部 | J26: 4 | L26: 4 | M26: =J26/L26 -> 1
A27: FL 佛州大区 汇总 | C27: 108 | D27: 2 | E27: 110 | G27: FL 佛州大区 汇总 | I27: =G27&""&H27 -> FL 佛州大区 汇总 | J27: 108 | K27: 2 | L27: 110 | M27: =J27/L27 -> 0.98181818
A28: GL 大湖大区 | C28: 2 | E28: 2 | G28: GL 大湖大区 | I28: =G28&""&H28 -> GL 大湖大区 | J28: 2 | L28: 2 | M28: =J28/L28 -> 1
A29: GL 大湖大区 | B29: CLE01 | C29: 1 | E29: 1 | G29: GL 大湖大区 | H29: CLE01 | I29: =G29&""&H29 -> GL 大湖大区CLE01 | J29: 1 | L29: 1 | M29: =J29/L29 -> 1
A30: GL 大湖大区 | B30: CM 中西部中心片区 | C30: 6 | E30: 6 | G30: GL 大湖大区 | H30: CM 中西部中心片区 | I30: =G30&""&H30 -> GL 大湖大区CM 中西部中心片区 | J30: 6 | L30: 6 | M30: =J30/L30 -> 1
A31: GL 大湖大区 | B31: CMH01 | C31: 1 | E31: 1 | G31: GL 大湖大区 | H31: CMH01 | I31: =G31&""&H31 -> GL 大湖大区CMH01 | J31: 1 | L31: 1 | M31: =J31/L31 -> 1
A32: GL 大湖大区 | B32: CVG.H | C32: 2 | E32: 2 | G32: GL 大湖大区 | H32: CVG.H | I32: =G32&""&H32 -> GL 大湖大区CVG.H | J32: 2 | L32: 2 | M32: =J32/L32 -> 1
A33: GL 大湖大区 | B33: EG 东大湖片区 | C33: 5 | E33: 5 | G33: GL 大湖大区 | H33: EG 东大湖片区 | I33: =G33&""&H33 -> GL 大湖大区EG 东大湖片区 | J33: 5 | L33: 5 | M33: =J33/L33 -> 1
A34: GL 大湖大区 | B34: IND01 | C34: 3 | E34: 3 | G34: GL 大湖大区 | H34: IND01 | I34: =G34&""&H34 -> GL 大湖大区IND01 | J34: 3 | L34: 3 | M34: =J34/L34 -> 1
A35: GL 大湖大区 | B35: MCI01 | C35: 2 | E35: 2 | G35: GL 大湖大区 | H35: MCI01 | I35: =G35&""&H35 -> GL 大湖大区MCI01 | J35: 2 | L35: 2 | M35: =J35/L35 -> 1
A36: GL 大湖大区 | B36: MKE01 | C36: 2 | E36: 2 | G36: GL 大湖大区 | H36: MKE01 | I36: =G36&""&H36 -> GL 大湖大区MKE01 | J36: 2 | L36: 2 | M36: =J36/L36 -> 1
A37: GL 大湖大区 | B37: NM 中西部北片区 | C37: 6 | E37: 6 | G37: GL 大湖大区 | H37: NM 中西部北片区 | I37: =G37&""&H37 -> GL 大湖大区NM 中西部北片区 | J37: 6 | L37: 6 | M37: =J37/L37 -> 1
A38: GL 大湖大区 | B38: ORD.H | C38: 28 | D38: 1 | E38: 29 | G38: GL 大湖大区 | H38: ORD.H | I38: =G38&""&H38 -> GL 大湖大区ORD.H | J38: 28 | K38: 1 | L38: 29 | M38: =J38/L38 -> 0.96551724
A39: GL 大湖大区 | B39: ORD01 | C39: 2 | E39: 2 | G39: GL 大湖大区 | H39: ORD01 | I39: =G39&""&H39 -> GL 大湖大区ORD01 | J39: 2 | L39: 2 | M39: =J39/L39 -> 1
A40: GL 大湖大区 | B40: WG 西大湖片区 | C40: 10 | E40: 10 | G40: GL 大湖大区 | H40: WG 西大湖片区 | I40: =G40&""&H40 -> GL 大湖大区WG 西大湖片区 | J40: 10 | L40: 10 | M40: =J40/L40 -> 1
A41: GL 大湖大区 | B41: 车辆管理部 | D41: 1 | E41: 1 | G41: GL 大湖大区 | H41: 车辆管理部 | I41: =G41&""&H41 -> GL 大湖大区车辆管理部 | K41: 1 | L41: 1 | M41: =J41/L41 -> 0
A42: GL 大湖大区 | B42: 揽收部 | C42: 5 | E42: 5 | G42: GL 大湖大区 | H42: 揽收部 | I42: =G42&""&H42 -> GL 大湖大区揽收部 | J42: 5 | L42: 5 | M42: =J42/L42 -> 1
...

Sheet 排班正确
A1: hub分类 | B1: HUB | H1: hub分类 | I1: HUB
A3: 计数项:工号 | C3: 是否排班正确 | H3: 计数项:工号 | K3: 是否排班正确
A4: 三级部门 | B4: 四级部门 | C4: / | D4: 不正确 | E4: 正确 | F4: 总计 | H4: 三级部门 | I4: 四级部门 | J4: 辅助 | K4: / | L4: 不正确 | M4: 正确 | N4: 总计 | O4: 正确率
A5: FL 佛州大区 | B5: MCO.H | D5: 3 | E5: 25 | F5: 28 | H5: FL 佛州大区 | I5: MCO.H | J5: =H5&""&I5 -> FL 佛州大区MCO.H | L5: 3 | M5: 25 | N5: 28 | O5: =M5/N5 -> 0.89285714
A6: FL 佛州大区 | B6: MIA.H | C6: 1 | D6: 7 | E6: 26 | F6: 34 | H6: FL 佛州大区 | I6: MIA.H | J6: =H6&""&I6 -> FL 佛州大区MIA.H | K6: 1 | L6: 7 | M6: 26 | N6: 34 | O6: =M6/N6 -> 0.76470588
A7: FL 佛州大区 汇总 | C7: 1 | D7: 10 | E7: 51 | F7: 62 | H7: FL 佛州大区 汇总 | J7: =H7&""&I7 -> FL 佛州大区 汇总 | K7: 1 | L7: 10 | M7: 51 | N7: 62 | O7: =M7/N7 -> 0.82258065
A8: GL 大湖大区 | B8: CVG.H | D8: 1 | E8: 1 | F8: 2 | H8: GL 大湖大区 | I8: CVG.H | J8: =H8&""&I8 -> GL 大湖大区CVG.H | L8: 1 | M8: 1 | N8: 2 | O8: =M8/N8 -> 0.5
A9: GL 大湖大区 | B9: ORD.H | C9: 1 | D9: 6 | E9: 22 | F9: 29 | H9: GL 大湖大区 | I9: ORD.H | J9: =H9&""&I9 -> GL 大湖大区ORD.H | K9: 1 | L9: 6 | M9: 22 | N9: 29 | O9: =M9/N9 -> 0.75862069
A10: GL 大湖大区 汇总 | C10: 1 | D10: 7 | E10: 23 | F10: 31 | H10: GL 大湖大区 汇总 | J10: =H10&""&I10 -> GL 大湖大区 汇总 | K10: 1 | L10: 7 | M10: 23 | N10: 31 | O10: =M10/N10 -> 0.74193548
A11: Ground项目部 | B11: OG 美东区 | D11: 1 | E11: 5 | F11: 6 | H11: Ground项目部 | I11: OG 美东区 | J11: =H11&""&I11 -> Ground项目部OG 美东区 | L11: 1 | M11: 5 | N11: 6 | O11: =M11/N11 -> 0.83333333
A12: Ground项目部 | B12: OG 美西区 | D12: 7 | E12: 9 | F12: 16 | H12: Ground项目部 | I12: OG 美西区 | J12: =H12&""&I12 -> Ground项目部OG 美西区 | L12: 7 | M12: 9 | N12: 16 | O12: =M12/N12 -> 0.5625
A13: Ground项目部 汇总 | D13: 8 | E13: 14 | F13: 22 | H13: Ground项目部 汇总 | J13: =H13&""&I13 -> Ground项目部 汇总 | L13: 8 | M13: 14 | N13: 22 | O13: =M13/N13 -> 0.63636364
A14: MS 中南大区 | B14: ATL.H | D14: 3 | E14: 16 | F14: 19 | H14: MS 中南大区 | I14: ATL.H | J14: =H14&""&I14 -> MS 中南大区ATL.H | L14: 3 | M14: 16 | N14: 19 | O14: =M14/N14 -> 0.84210526
A15: MS 中南大区 | B15: CLT.H | D15: 3 | E15: 8 | F15: 11 | H15: MS 中南大区 | I15: CLT.H | J15: =H15&""&I15 -> MS 中南大区CLT.H | L15: 3 | M15: 8 | N15: 11 | O15: =M15/N15 -> 0.72727273
A16: MS 中南大区 | B16: PDK.H | E16: 1 | F16: 1 | H16: MS 中南大区 | I16: PDK.H | J16: =H16&""&I16 -> MS 中南大区PDK.H | M16: 1 | N16: 1 | O16: =M16/N16 -> 1
A17: MS 中南大区 汇总 | D17: 6 | E17: 25 | F17: 31 | H17: MS 中南大区 汇总 | J17: =H17&""&I17 -> MS 中南大区 汇总 | L17: 6 | M17: 25 | N17: 31 | O17: =M17/N17 -> 0.80645161
A18: NE 东北大区 | B18: BWI.H | D18: 4 | E18: 2 | F18: 6 | H18: NE 东北大区 | I18: BWI.H | J18: =H18&""&I18 -> NE 东北大区BWI.H | L18: 4 | M18: 2 | N18: 6 | O18: =M18/N18 -> 0.33333333
A19: NE 东北大区 | B19: EWR.H | D19: 14 | E19: 24 | F19: 38 | H19: NE 东北大区 | I19: EWR.H | J19: =H19&""&I19 -> NE 东北大区EWR.H | L19: 14 | M19: 24 | N19: 38 | O19: =M19/N19 -> 0.63157895
A20: NE 东北大区 | B20: JFK.H | E20: 15 | F20: 15 | H20: NE 东北大区 | I20: JFK.H | J20: =H20&""&I20 -> NE 东北大区JFK.H | M20: 15 | N20: 15 | O20: =M20/N20 -> 1
A21: NE 东北大区 汇总 | D21: 18 | E21: 41 | F21: 59 | H21: NE 东北大区 汇总 | J21: =H21&""&I21 -> NE 东北大区 汇总 | L21: 18 | M21: 41 | N21: 59 | O21: =M21/N21 -> 0.69491525
A22: TX 德州大区 | B22: DFW.H | D22: 2 | E22: 23 | F22: 25 | H22: TX 德州大区 | I22: DFW.H | J22: =H22&""&I22 -> TX 德州大区DFW.H | L22: 2 | M22: 23 | N22: 25 | O22: =M22/N22 -> 0.92
A23: TX 德州大区 | B23: IAH.H | D23: 1 | E23: 17 | F23: 18 | H23: TX 德州大区 | I23: IAH.H | J23: =H23&""&I23 -> TX 德州大区IAH.H | L23: 1 | M23: 17 | N23: 18 | O23: =M23/N23 -> 0.94444444
A24: TX 德州大区 汇总 | D24: 3 | E24: 40 | F24: 43 | H24: TX 德州大区 汇总 | J24: =H24&""&I24 -> TX 德州大区 汇总 | L24: 3 | M24: 40 | N24: 43 | O24: =M24/N24 -> 0.93023256
A25: WE 美西大区 | B25: CNO.H | D25: 14 | E25: 34 | F25: 48 | H25: WE 美西大区 | I25: CNO.H | J25: =H25&""&I25 -> WE 美西大区CNO.H | L25: 14 | M25: 34 | N25: 48 | O25: =M25/N25 -> 0.70833333
A26: WE 美西大区 | B26: LAV.H | D26: 9 | E26: 32 | F26: 41 | H26: WE 美西大区 | I26: LAV.H | J26: =H26&""&I26 -> WE 美西大区LAV.H | L26: 9 | M26: 32 | N26: 41 | O26: =M26/N26 -> 0.7804878
A27: WE 美西大区 汇总 | D27: 23 | E27: 66 | F27: 89 | H27: WE 美西大区 汇总 | J27: =H27&""&I27 -> WE 美西大区 汇总 | L27: 23 | M27: 66 | N27: 89 | O27: =M27/N27 -> 0.74157303
A28: 总计 | C28: 2 | D28: 75 | E28: 260 | F28: 337 | H28: 总计 | J28: =H28&""&I28 -> 总计 | K28: 2 | L28: 75 | M28: 260 | N28: 337 | O28: =M28/N28 -> 0.77151335

Sheet 缺卡
A3: 三级部门 | B3: 四级部门 | C3: 求和项:缺卡次数 | D3: 求和项:标准打卡数 | F3: 三级部门 | G3: 四级部门 | H3: 辅助 | I3: 求和项:缺卡次数 | J3: 求和项:标准打卡数 | K3: queka1
A4: AD 行政部 | C4: 20 | D4: 60 | F4: AD 行政部 | H4: =F4&""&G4 -> AD 行政部 | I4: 20 | J4: 60 | K4: =I4/J4 -> 0.33333333
A5: AS 审计监察部 | C5: 2 | D5: 4 | F5: AS 审计监察部 | H5: =F5&""&G5 -> AS 审计监察部 | I5: 2 | J5: 4 | K5: =I5/J5 -> 0.5
A6: BD 本地客户部 | C6: 60 | D6: 60 | F6: BD 本地客户部 | H6: =F6&""&G6 -> BD 本地客户部 | I6: 60 | J6: 60 | K6: =I6/J6 -> 1
A7: BM 品牌市场部 | C7: 6 | D7: 12 | F7: BM 品牌市场部 | H7: =F7&""&G7 -> BM 品牌市场部 | I7: 6 | J7: 12 | K7: =I7/J7 -> 0.5
A8: CM 运力管理部 | C8: 29 | D8: 44 | F8: CM 运力管理部 | H8: =F8&""&G8 -> CM 运力管理部 | I8: 29 | J8: 44 | K8: =I8/J8 -> 0.65909091
A9: CS 客户服务部 | C9: 3 | D9: 28 | F9: CS 客户服务部 | H9: =F9&""&G9 -> CS 客户服务部 | I9: 3 | J9: 28 | K9: =I9/J9 -> 0.10714286
A10: DO 数字运营部 | C10: 23 | D10: 40 | F10: DO 数字运营部 | H10: =F10&""&G10 -> DO 数字运营部 | I10: 23 | J10: 40 | K10: =I10/J10 -> 0.575
A11: FL 佛州大区 | C11: 2 | D11: 4 | F11: FL 佛州大区 | H11: =F11&""&G11 -> FL 佛州大区 | I11: 2 | J11: 4 | K11: =I11/J11 -> 0.5
A12: FL 佛州大区 | B12: FTM01 | C12: 6 | D12: 12 | F12: FL 佛州大区 | G12: FTM01 | H12: =F12&""&G12 -> FL 佛州大区FTM01 | I12: 6 | J12: 12 | K12: =I12/J12 -> 0.5
A13: FL 佛州大区 | B13: MCO.H | C13: 5 | D13: 68 | F13: FL 佛州大区 | G13: MCO.H | H13: =F13&""&G13 -> FL 佛州大区MCO.H | I13: 5 | J13: 68 | K13: =I13/J13 -> 0.073529412
A14: FL 佛州大区 | B14: MCO01 | C14: 0 | D14: 8 | F14: FL 佛州大区 | G14: MCO01 | H14: =F14&""&G14 -> FL 佛州大区MCO01 | I14: 0 | J14: 8 | K14: =I14/J14 -> 0
A15: FL 佛州大区 | B15: MF 中佛片区 | C15: 10 | D15: 16 | F15: FL 佛州大区 | G15: MF 中佛片区 | H15: =F15&""&G15 -> FL 佛州大区MF 中佛片区 | I15: 10 | J15: 16 | K15: =I15/J15 -> 0.625
A16: FL 佛州大区 | B16: MIA.H | C16: 38 | D16: 112 | F16: FL 佛州大区 | G16: MIA.H | H16: =F16&""&G16 -> FL 佛州大区MIA.H | I16: 38 | J16: 112 | K16: =I16/J16 -> 0.33928571
A17: FL 佛州大区 | B17: MIA01 | C17: 1 | D17: 12 | F17: FL 佛州大区 | G17: MIA01 | H17: =F17&""&G17 -> FL 佛州大区MIA01 | I17: 1 | J17: 12 | K17: =I17/J17 -> 0.083333333
A18: FL 佛州大区 | B18: NF 北佛片区 | C18: 6 | D18: 24 | F18: FL 佛州大区 | G18: NF 北佛片区 | H18: =F18&""&G18 -> FL 佛州大区NF 北佛片区 | I18: 6 | J18: 24 | K18: =I18/J18 -> 0.25
A19: FL 佛州大区 | B19: OCF01 | C19: 2 | D19: 4 | F19: FL 佛州大区 | G19: OCF01 | H19: =F19&""&G19 -> FL 佛州大区OCF01 | I19: 2 | J19: 4 | K19: =I19/J19 -> 0.5
A20: FL 佛州大区 | B20: SF 南佛片区 | C20: 6 | D20: 24 | F20: FL 佛州大区 | G20: SF 南佛片区 | H20: =F20&""&G20 -> FL 佛州大区SF 南佛片区 | I20: 6 | J20: 24 | K20: =I20/J20 -> 0.25
A21: FL 佛州大区 | B21: SRQ01 | C21: 0 | D21: 4 | F21: FL 佛州大区 | G21: SRQ01 | H21: =F21&""&G21 -> FL 佛州大区SRQ01 | I21: 0 | J21: 4 | K21: =I21/J21 -> 0
A22: FL 佛州大区 | B22: TPA01 | C22: 5 | D22: 8 | F22: FL 佛州大区 | G22: TPA01 | H22: =F22&""&G22 -> FL 佛州大区TPA01 | I22: 5 | J22: 8 | K22: =I22/J22 -> 0.625
A23: FL 佛州大区 | B23: WF 西佛片区 | C23: 7 | D23: 16 | F23: FL 佛州大区 | G23: WF 西佛片区 | H23: =F23&""&G23 -> FL 佛州大区WF 西佛片区 | I23: 7 | J23: 16 | K23: =I23/J23 -> 0.4375
A24: FL 佛州大区 | B24: WPB01 | C24: 0 | D24: 0 | F24: FL 佛州大区 | G24: WPB01 | H24: =F24&""&G24 -> FL 佛州大区WPB01 | I24: 0 | J24: 0 | K24: /
A25: FL 佛州大区 | B25: 运营支持部 | C25: 3 | D25: 16 | F25: FL 佛州大区 | G25: 运营支持部 | H25: =F25&""&G25 -> FL 佛州大区运营支持部 | I25: 3 | J25: 16 | K25: =I25/J25 -> 0.1875
A26: FL 佛州大区 汇总 | C26: 91 | D26: 328 | F26: FL 佛州大区 汇总 | H26: =F26&""&G26 -> FL 佛州大区 汇总 | I26: 91 | J26: 328 | K26: =I26/J26 -> 0.27743902
A27: GL 大湖大区 | C27: 2 | D27: 4 | F27: GL 大湖大区 | H27: =F27&""&G27 -> GL 大湖大区 | I27: 2 | J27: 4 | K27: =I27/J27 -> 0.5
A28: GL 大湖大区 | B28: CLE01 | C28: 0 | D28: 4 | F28: GL 大湖大区 | G28: CLE01 | H28: =F28&""&G28 -> GL 大湖大区CLE01 | I28: 0 | J28: 4 | K28: =I28/J28 -> 0
A29: GL 大湖大区 | B29: CM 中西部中心片区 | C29: 4 | D29: 12 | F29: GL 大湖大区 | G29: CM 中西部中心片区 | H29: =F29&""&G29 -> GL 大湖大区CM 中西部中心片区 | I29: 4 | J29: 12 | K29: =I29/J29 -> 0.33333333
A30: GL 大湖大区 | B30: CMH01 | C30: 4 | D30: 4 | F30: GL 大湖大区 | G30: CMH01 | H30: =F30&""&G30 -> GL 大湖大区CMH01 | I30: 4 | J30: 4 | K30: =I30/J30 -> 1
A31: GL 大湖大区 | B31: CVG.H | C31: 2 | D31: 4 | F31: GL 大湖大区 | G31: CVG.H | H31: =F31&""&G31 -> GL 大湖大区CVG.H | I31: 2 | J31: 4 | K31: =I31/J31 -> 0.5
A32: GL 大湖大区 | B32: EG 东大湖片区 | C32: 3 | D32: 12 | F32: GL 大湖大区 | G32: EG 东大湖片区 | H32: =F32&""&G32 -> GL 大湖大区EG 东大湖片区 | I32: 3 | J32: 12 | K32: =I32/J32 -> 0.25
A33: GL 大湖大区 | B33: IND01 | C33: 0 | D33: 4 | F33: GL 大湖大区 | G33: IND01 | H33: =F33&""&G33 -> GL 大湖大区IND01 | I33: 0 | J33: 4 | K33: =I33/J33 -> 0
A34: GL 大湖大区 | B34: MCI01 | C34: 0 | D34: 4 | F34: GL 大湖大区 | G34: MCI01 | H34: =F34&""&G34 -> GL 大湖大区MCI01 | I34: 0 | J34: 4 | K34: =I34/J34 -> 0
A35: GL 大湖大区 | B35: MKE01 | C35: 6 | D35: 8 | F35: GL 大湖大区 | G35: MKE01 | H35: =F35&""&G35 -> GL 大湖大区MKE01 | I35: 6 | J35: 8 | K35: =I35/J35 -> 0.75
A36: GL 大湖大区 | B36: NM 中西部北片区 | C36: 9 | D36: 20 | F36: GL 大湖大区 | G36: NM 中西部北片区 | H36: =F36&""&G36 -> GL 大湖大区NM 中西部北片区 | I36: 9 | J36: 20 | K36: =I36/J36 -> 0.45
A37: GL 大湖大区 | B37: ORD.H | C37: 29 | D37: 88 | F37: GL 大湖大区 | G37: ORD.H | H37: =F37&""&G37 -> GL 大湖大区ORD.H | I37: 29 | J37: 88 | K37: =I37/J37 -> 0.32954545
A38: GL 大湖大区 | B38: ORD01 | C38: 4 | D38: 4 | F38: GL 大湖大区 | G38: ORD01 | H38: =F38&""&G38 -> GL 大湖大区ORD01 | I38: 4 | J38: 4 | K38: =I38/J38 -> 1
A39: GL 大湖大区 | B39: WG 西大湖片区 | C39: 19 | D39: 32 | F39: GL 大湖大区 | G39: WG 西大湖片区 | H39: =F39&""&G39 -> GL 大湖大区WG 西大湖片区 | I39: 19 | J39: 32 | K39: =I39/J39 -> 0.59375
A40: GL 大湖大区 | B40: 车辆管理部 | C40: 0 | D40: 0 | F40: GL 大湖大区 | G40: 车辆管理部 | H40: =F40&""&G40 -> GL 大湖大区车辆管理部 | I40: 0 | J40: 0 | K40: /
A41: GL 大湖大区 | B41: 揽收部 | C41: 6 | D41: 20 | F41: GL 大湖大区 | G41: 揽收部 | H41: =F41&""&G41 -> GL 大湖大区揽收部 | I41: 6 | J41: 20 | K41: =I41/J41 -> 0.3
A42: GL 大湖大区 | B42: 运营支持部 | C42: 12 | D42: 28 | F42: GL 大湖大区 | G42: 运营支持部 | H42: =F42&""&G42 -> GL 大湖大区运营支持部 | I42: 12 | J42: 28 | K42: =I42/J42 -> 0.42857143
...

Sheet 每日打卡工时推送模版
A1: 考勤日期 | B1: 姓名 | C1: 工号 | D1: 三级部门 | E1: 四级部门 | F1: 五级部门 | G1: hub分类 | H1: 辅助 | I1: 职位 | J1: 班次名称 | K1: 班次上班时间 | L1: 班次下班时间 | M1: 首打卡时间 | N1: 末打卡时间 | O1: 是否排班正确 | P1: 居家办公工时（全）合计 | Q1: 每日总工时(公式：末打卡-首打卡-班次午休时间+居家办公时长)合计 | R1: 居家办公合计（审批中） | S1: 每日总工时(公式：末打卡-首打卡-班次午休时间+居家办公时长)合计 | T1: 日超8H | U1: 是否日超8H | V1: 累计总工时 | W1: 本周加班工时 | X1: 班次内打卡次数 | Y1: 标准打卡数 | Z1: 缺卡次数 | AA1: 是否排班 | AB1: 备注（GF）
A2: 考勤日期 | B2: 姓名 | C2: 工号 | D2: 三级部门 | E2: 四级部门 | F2: 五级部门 | G2: hub分类 | H2: 辅助 | I2: 职位 | J2: 班次名称 | K2: 班次上班时间 | L2: 班次下班时间 | M2: 首打卡时间 | N2: 末打卡时间 | O2: 是否排班正确 | P2: 居家办公工时（全）合计 | Q2: 每日总工时(公式：末打卡-首打卡-班次午休时间+居家办公时长)合计 | R2: 居家办公合计（审批中） | S2: 每日总工时(公式：末打卡-首打卡-班次午休时间+居家办公时长)合计 | T2: 日超8H | U2: 是否日超8H | V2: 累计总工时 | W2: 本周加班工时 | X2: 班次内打卡次数 | Y2: 标准打卡数 | Z2: 缺卡次数 | AA2: 是否排班 | AB2: 备注（GF） | AC2: 离职日期 | AD2: 区域BP | AE2: 区长 | AF2: 负责人 | AG2: 仓长 | AH2: 字段 2 | AI2: 字段 3
B3: Alessan South | C3: GL502870 | D3: MS 中南大区 | E3: RE 北卡和东南海岸片区 | F3: ILM01 | H3: =D3&E3&F3 -> MS 中南大区RE 北卡和东南海岸片区ILM01 | I3: Warehouse Operator 操作员(兼) | O3: / | P3: 0 | Q3: 0 | R3: 0 | S3: =Q3+R3 -> 0 | T3: =IF(S3-8>0,S3-8,0) -> 0 | U3: =IF(T3=0,"否","是") -> 否 | V3: =VLOOKUP($C3,[4]Sheet1!$B:$AN,39,FALSE) -> 0 | W3: 0 | X3: 0 | Y3: 0 | Z3: =IF(Y3-X3>=0,Y3-X3,0) -> 0 | AA3: =IF(J3="","否","是") -> 否 | AC3: =VLOOKUP(C3,[1]Sheet1!$C:$O,13,FALSE) -> #N/A | AD3: =VLOOKUP($H3,'[3]0509人员排班情况 副本'!$G:$U,12,FALSE) -> 欧阳迎春Flower（Yingchun Ouyang） | AE3: =VLOOKUP($H3,'[3]0509人员排班情况 副本'!$G:$U,13,FALSE) -> 杨云飞 | AF3: =VLOOKUP($H3,'[3]0509人员排班情况 副本'!$G:$U,14,FALSE) -> 0 | AG3: =VLOOKUP($H3,'[3]0509人员排班情况 副本'!$G:$U,15,FALSE) -> 0
B4: Caleb Aaron Kenmar | C4: GL502898 | D4: MS 中南大区 | E4: AS 亚特兰大和南阿拉巴马片区 | F4: MOB01 | H4: =D4&E4&F4 -> MS 中南大区AS 亚特兰大和南阿拉巴马片区MOB01 | I4: Warehouse Operator 操作员 | O4: / | P4: 0 | Q4: 0 | R4: 0 | S4: =Q4+R4 -> 0 | T4: =IF(S4-8>0,S4-8,0) -> 0 | U4: =IF(T4=0,"否","是") -> 否 | V4: =VLOOKUP($C4,[4]Sheet1!$B:$AN,39,FALSE) -> 0 | W4: 0 | X4: 0 | Y4: 0 | Z4: =IF(Y4-X4>=0,Y4-X4,0) -> 0 | AA4: =IF(J4="","否","是") -> 否 | AC4: =VLOOKUP(C4,[1]Sheet1!$C:$O,13,FALSE) -> #N/A | AD4: =VLOOKUP($H4,'[3]0509人员排班情况 副本'!$G:$U,12,FALSE) -> 欧阳迎春Flower（Yingchun Ouyang） | AE4: =VLOOKUP($H4,'[3]0509人员排班情况 副本'!$G:$U,13,FALSE) -> 杨云飞 | AF4: =VLOOKUP($H4,'[3]0509人员排班情况 副本'!$G:$U,14,FALSE) -> 曾令桓（Linghuan Zeng） | AG4: =VLOOKUP($H4,'[3]0509人员排班情况 副本'!$G:$U,15,FALSE) -> 0
B5: Kareem Stuart | C5: GL502718 | D5: Ground项目部 | E5: OG 美南区 | F5: ATL.G | H5: =D5&E5&F5 -> Ground项目部OG 美南区ATL.G | I5: Dispatcher 调度员 | O5: / | P5: 0 | Q5: 0 | R5: 0 | S5: =Q5+R5 -> 0 | T5: =IF(S5-8>0,S5-8,0) -> 0 | U5: =IF(T5=0,"否","是") -> 否 | V5: =VLOOKUP($C5,[4]Sheet1!$B:$AN,39,FALSE) -> 0 | W5: 0 | X5: 0 | Y5: 0 | Z5: =IF(Y5-X5>=0,Y5-X5,0) -> 0 | AA5: =IF(J5="","否","是") -> 否 | AC5: =VLOOKUP(C5,[1]Sheet1!$C:$O,13,FALSE) -> #N/A | AD5: =VLOOKUP($H5,'[3]0509人员排班情况 副本'!$G:$U,12,FALSE) -> 王安琪 (Anqi Wang),张朱同 Thomson（Zhutong Zhang） | AE5: =VLOOKUP($H5,'[3]0509人员排班情况 副本'!$G:$U,13,FALSE) -> 陈锦昭 | AF5: =VLOOKUP($H5,'[3]0509人员排班情况 副本'!$G:$U,14,FALSE) -> 金筱燕Sharon（Xiaoyan Jin） | AG5: =VLOOKUP($H5,'[3]0509人员排班情况 副本'!$G:$U,15,FALSE) -> 0
B6: Tara S Austin | C6: GL502869 | D6: MS 中南大区 | E6: RE 北卡和东南海岸片区 | F6: MYR01 | H6: =D6&E6&F6 -> MS 中南大区RE 北卡和东南海岸片区MYR01 | I6: Warehouse Operator 操作员(兼) | O6: / | P6: 0 | Q6: 0 | R6: 0 | S6: =Q6+R6 -> 0 | T6: =IF(S6-8>0,S6-8,0) -> 0 | U6: =IF(T6=0,"否","是") -> 否 | V6: =VLOOKUP($C6,[4]Sheet1!$B:$AN,39,FALSE) -> 0 | W6: 0 | X6: 0 | Y6: 0 | Z6: =IF(Y6-X6>=0,Y6-X6,0) -> 0 | AA6: =IF(J6="","否","是") -> 否 | AC6: =VLOOKUP(C6,[1]Sheet1!$C:$O,13,FALSE) -> #N/A | AD6: =VLOOKUP($H6,'[3]0509人员排班情况 副本'!$G:$U,12,FALSE) -> 欧阳迎春Flower（Yingchun Ouyang） | AE6: =VLOOKUP($H6,'[3]0509人员排班情况 副本'!$G:$U,13,FALSE) -> 杨云飞 | AF6: =VLOOKUP($H6,'[3]0509人员排班情况 副本'!$G:$U,14,FALSE) -> 0 | AG6: =VLOOKUP($H6,'[3]0509人员排班情况 副本'!$G:$U,15,FALSE) -> 0
B7: 刘建好Gaby（Jianhao Liu) | C7: GL502829 | D7: FL 佛州大区 | E7: MIA.H | F7: 综办组 | G7: HUB | H7: =D7&E7&F7 -> FL 佛州大区MIA.H综办组 | I7: Warehouse Clerk 仓库文员 | O7: / | P7: 0 | Q7: 0 | R7: 0 | S7: =Q7+R7 -> 0 | T7: =IF(S7-8>0,S7-8,0) -> 0 | U7: =IF(T7=0,"否","是") -> 否 | V7: =VLOOKUP($C7,[4]Sheet1!$B:$AN,39,FALSE) -> 0 | W7: 0 | X7: 0 | Y7: 0 | Z7: =IF(Y7-X7>=0,Y7-X7,0) -> 0 | AA7: =IF(J7="","否","是") -> 否 | AC7: =VLOOKUP(C7,[1]Sheet1!$C:$O,13,FALSE) -> #N/A | AD7: =VLOOKUP($H7,'[3]0509人员排班情况 副本'!$G:$U,12,FALSE) -> Natalia (Natalia Padilla),孙婕 Jasmine（Sunjie） | AE7: =VLOOKUP($H7,'[3]0509人员排班情况 副本'!$G:$U,13,FALSE) -> 贺子强Jeff (Ziqiang He) | AF7: =VLOOKUP($H7,'[3]0509人员排班情况 副本'!$G:$U,14,FALSE) -> Minqing (Minqing Xu),罗煜雄 Mike (Yuxiong Luo) | AG7: =VLOOKUP($H7,'[3]0509人员排班情况 副本'!$G:$U,15,FALSE) -> 0
B8: 刘梓宸 James (Zichen Liu) | C8: GL500866 | D8: GL 大湖大区 | E8: ORD.H | G8: HUB | H8: =D8&E8&F8 -> GL 大湖大区ORD.H | I8: Deputy Hub Head（Probation） 副仓长（见习） | O8: / | P8: 0 | Q8: 0 | R8: 0 | S8: =Q8+R8 -> 0 | T8: =IF(S8-8>0,S8-8,0) -> 0 | U8: =IF(T8=0,"否","是") -> 否 | V8: =VLOOKUP($C8,[4]Sheet1!$B:$AN,39,FALSE) -> 0 | W8: 0 | X8: 0 | Y8: 0 | Z8: =IF(Y8-X8>=0,Y8-X8,0) -> 0 | AA8: =IF(J8="","否","是") -> 否 | AC8: =VLOOKUP(C8,[1]Sheet1!$C:$O,13,FALSE) -> #N/A | AD8: =VLOOKUP($H8,'[3]0509人员排班情况 副本'!$G:$U,12,FALSE) -> 王晓丹 Jasmine（Xiaodan Wang）,周延舒Isabel（Yanshu Zhou） | AE8: =VLOOKUP($H8,'[3]0509人员排班情况 副本'!$G:$U,13,FALSE) -> 张骥Ji Zhang (Ji Zhang) | AF8: =VLOOKUP($H8,'[3]0509人员排班情况 副本'!$G:$U,14,FALSE) -> Minqing (Minqing Xu),罗煜雄 Mike (Yuxiong Luo) | AG8: =VLOOKUP($H8,'[3]0509人员排班情况 副本'!$G:$U,15,FALSE) -> 0
B9: 吴金生 Jason (Jinsheng Wu) | C9: GL500670 | D9: FL 佛州大区 | E9: SF 南佛片区 | H9: =D9&E9&F9 -> FL 佛州大区SF 南佛片区 | I9: District Head 片区长 | O9: / | P9: 0 | Q9: 0 | R9: 0 | S9: =Q9+R9 -> 0 | T9: =IF(S9-8>0,S9-8,0) -> 0 | U9: =IF(T9=0,"否","是") -> 否 | V9: =VLOOKUP($C9,[4]Sheet1!$B:$AN,39,FALSE) -> 0 | W9: 0 | X9: 0 | Y9: 0 | Z9: =IF(Y9-X9>=0,Y9-X9,0) -> 0 | AA9: =IF(J9="","否","是") -> 否 | AC9: =VLOOKUP(C9,[1]Sheet1!$C:$O,13,FALSE) -> #N/A | AD9: =VLOOKUP($H9,'[3]0509人员排班情况 副本'!$G:$U,12,FALSE) -> Natalia (Natalia Padilla),孙婕 Jasmine（Sunjie） | AE9: =VLOOKUP($H9,'[3]0509人员排班情况 副本'!$G:$U,13,FALSE) -> 贺子强Jeff (Ziqiang He) | AF9: =VLOOKUP($H9,'[3]0509人员排班情况 副本'!$G:$U,14,FALSE) -> 0 | AG9: =VLOOKUP($H9,'[3]0509人员排班情况 副本'!$G:$U,15,FALSE) -> 0
B10: 左越 Phil (Yue Zuo) | C10: GL502814 | D10: MS 中南大区 | E10: CS 夏洛特及周边片区 | F10: CLT01 | H10: =D10&E10&F10 -> MS 中南大区CS 夏洛特及周边片区CLT01 | I10: Station Operations Specialist 站点运营专员 | O10: / | P10: 0 | Q10: 0 | R10: 0 | S10: =Q10+R10 -> 0 | T10: =IF(S10-8>0,S10-8,0) -> 0 | U10: =IF(T10=0,"否","是") -> 否 | V10: =VLOOKUP($C10,[4]Sheet1!$B:$AN,39,FALSE) -> 0 | W10: 0 | X10: 0 | Y10: 0 | Z10: =IF(Y10-X10>=0,Y10-X10,0) -> 0 | AA10: =IF(J10="","否","是") -> 否 | AC10: =VLOOKUP(C10,[1]Sheet1!$C:$O,13,FALSE) -> #N/A | AD10: =VLOOKUP($H10,'[3]0509人员排班情况 副本'!$G:$U,12,FALSE) -> 欧阳迎春Flower（Yingchun Ouyang） | AE10: =VLOOKUP($H10,'[3]0509人员排班情况 副本'!$G:$U,13,FALSE) -> 杨云飞 | AF10: =VLOOKUP($H10,'[3]0509人员排班情况 副本'!$G:$U,14,FALSE) -> 郭丞芸Lexie(Chengyun Kuo) | AG10: =VLOOKUP($H10,'[3]0509人员排班情况 副本'!$G:$U,15,FALSE) -> 0
B11: 张译丹 Edan （Yidan Zhang） | C11: GL501628 | D11: MS 中南大区 | E11: CS 夏洛特及周边片区 | F11: CLT02 | H11: =D11&E11&F11 -> MS 中南大区CS 夏洛特及周边片区CLT02 | I11: Station Operations Specialist 站点运营专员 | O11: / | P11: 0 | Q11: 0 | R11: 0 | S11: =Q11+R11 -> 0 | T11: =IF(S11-8>0,S11-8,0) -> 0 | U11: =IF(T11=0,"否","是") -> 否 | V11: =VLOOKUP($C11,[4]Sheet1!$B:$AN,39,FALSE) -> 0 | W11: 0 | X11: 0 | Y11: 0 | Z11: =IF(Y11-X11>=0,Y11-X11,0) -> 0 | AA11: =IF(J11="","否","是") -> 否 | AC11: =VLOOKUP(C11,[1]Sheet1!$C:$O,13,FALSE) -> #N/A | AD11: =VLOOKUP($H11,'[3]0509人员排班情况 副本'!$G:$U,12,FALSE) -> 欧阳迎春Flower（Yingchun Ouyang） | AE11: =VLOOKUP($H11,'[3]0509人员排班情况 副本'!$G:$U,13,FALSE) -> 杨云飞 | AF11: =VLOOKUP($H11,'[3]0509人员排班情况 副本'!$G:$U,14,FALSE) -> 郭丞芸Lexie(Chengyun Kuo) | AG11: =VLOOKUP($H11,'[3]0509人员排班情况 副本'!$G:$U,15,FALSE) -> 0
B12: 李育珊Amber （Yushan Li） | C12: GL502554 | D12: TX 德州大区 | E12: NT 北德州片区 | F12: SPR01 | H12: =D12&E12&F12 -> TX 德州大区NT 北德州片区SPR01 | I12: Station Operations Specialist 站点运营专员 | O12: / | P12: 0 | Q12: 0 | R12: 0 | S12: =Q12+R12 -> 0 | T12: =IF(S12-8>0,S12-8,0) -> 0 | U12: =IF(T12=0,"否","是") -> 否 | V12: =VLOOKUP($C12,[4]Sheet1!$B:$AN,39,FALSE) -> 0 | W12: 0 | X12: 0 | Y12: 0 | Z12: =IF(Y12-X12>=0,Y12-X12,0) -> 0 | AA12: =IF(J12="","否","是") -> 否 | AC12: =VLOOKUP(C12,[1]Sheet1!$C:$O,13,FALSE) -> #N/A | AD12: =VLOOKUP($H12,'[3]0509人员排班情况 副本'!$G:$U,12,FALSE) -> 肖芦莉Lily (Luli Xiao) | AE12: =VLOOKUP($H12,'[3]0509人员排班情况 副本'!$G:$U,13,FALSE) -> 张骥Ji Zhang (Ji Zhang) | AF12: =VLOOKUP($H12,'[3]0509人员排班情况 副本'!$G:$U,14,FALSE) -> 何琼joan(Qiong He) | AG12: =VLOOKUP($H12,'[3]0509人员排班情况 副本'!$G:$U,15,FALSE) -> 0
B13: 李致远Brian (Zhiyuan Li) | C13: GL502889 | D13: NE 东北大区 | E13: NY 纽约片区 | F13: LGA01 | H13: =D13&E13&F13 -> NE 东北大区NY 纽约片区LGA01 | I13: Station Operations Specialist 站点运营专员 | O13: / | P13: 0 | Q13: 0 | R13: 0 | S13: =Q13+R13 -> 0 | T13: =IF(S13-8>0,S13-8,0) -> 0 | U13: =IF(T13=0,"否","是") -> 否 | V13: =VLOOKUP($C13,[4]Sheet1!$B:$AN,39,FALSE) -> 0 | W13: 0 | X13: 0 | Y13: 0 | Z13: =IF(Y13-X13>=0,Y13-X13,0) -> 0 | AA13: =IF(J13="","否","是") -> 否 | AC13: =VLOOKUP(C13,[1]Sheet1!$C:$O,13,FALSE) -> #N/A | AD13: =VLOOKUP($H13,'[3]0509人员排班情况 副本'!$G:$U,12,FALSE) -> 孙可君Monica（Kejun Sun） | AE13: =VLOOKUP($H13,'[3]0509人员排班情况 副本'!$G:$U,13,FALSE) -> 马聪Cong (Cong Ma) | AF13: =VLOOKUP($H13,'[3]0509人员排班情况 副本'!$G:$U,14,FALSE) -> 朱晗宇 Peter (Hanyu Zhu) | AG13: =VLOOKUP($H13,'[3]0509人员排班情况 副本'!$G:$U,15,FALSE) -> 0
B14: 胡丹妮Danni（Danni Hu） | C14: GL500675 | D14: GL 大湖大区 | E14: 车辆管理部 | H14: =D14&E14&F14 -> GL 大湖大区车辆管理部 | I14: Deputy Vehicle Management Supervisor 车辆管理部副主管 | O14: / | P14: 0 | Q14: 0 | R14: 0 | S14: =Q14+R14 -> 0 | T14: =IF(S14-8>0,S14-8,0) -> 0 | U14: =IF(T14=0,"否","是") -> 否 | V14: =VLOOKUP($C14,[4]Sheet1!$B:$AN,39,FALSE) -> 0 | W14: 0 | X14: 0 | Y14: 0 | Z14: =IF(Y14-X14>=0,Y14-X14,0) -> 0 | AA14: =IF(J14="","否","是") -> 否 | AC14: =VLOOKUP(C14,[1]Sheet1!$C:$O,13,FALSE) -> #N/A | AD14: =VLOOKUP($H14,'[3]0509人员排班情况 副本'!$G:$U,12,FALSE) -> 王晓丹 Jasmine（Xiaodan Wang）,周延舒Isabel（Yanshu Zhou） | AE14: =VLOOKUP($H14,'[3]0509人员排班情况 副本'!$G:$U,13,FALSE) -> 张骥Ji Zhang (Ji Zhang) | AF14: =VLOOKUP($H14,'[3]0509人员排班情况 副本'!$G:$U,14,FALSE) -> 0 | AG14: =VLOOKUP($H14,'[3]0509人员排班情况 副本'!$G:$U,15,FALSE) -> 0
B15: 赵旸悦𮭦Fiona（Yangyuechen Zhao） | C15: GL502418 | D15: MS 中南大区 | E15: CS 夏洛特及周边片区 | F15: CLT01 | H15: =D15&E15&F15 -> MS 中南大区CS 夏洛特及周边片区CLT01 | I15: Station Operations Specialist 站点运营专员 | O15: / | P15: 0 | Q15: 0 | R15: 0 | S15: =Q15+R15 -> 0 | T15: =IF(S15-8>0,S15-8,0) -> 0 | U15: =IF(T15=0,"否","是") -> 否 | V15: =VLOOKUP($C15,[4]Sheet1!$B:$AN,39,FALSE) -> 0 | W15: 0 | X15: 0 | Y15: 0 | Z15: =IF(Y15-X15>=0,Y15-X15,0) -> 0 | AA15: =IF(J15="","否","是") -> 否 | AC15: =VLOOKUP(C15,[1]Sheet1!$C:$O,13,FALSE) -> #N/A | AD15: =VLOOKUP($H15,'[3]0509人员排班情况 副本'!$G:$U,12,FALSE) -> 欧阳迎春Flower（Yingchun Ouyang） | AE15: =VLOOKUP($H15,'[3]0509人员排班情况 副本'!$G:$U,13,FALSE) -> 杨云飞 | AF15: =VLOOKUP($H15,'[3]0509人员排班情况 副本'!$G:$U,14,FALSE) -> 郭丞芸Lexie(Chengyun Kuo) | AG15: =VLOOKUP($H15,'[3]0509人员排班情况 副本'!$G:$U,15,FALSE) -> 0
B16: 邱俊达Jayden（Junda Qiu） | C16: GL502769 | D16: Ground项目部 | E16: OG 美南区 | F16: AT303 | H16: =D16&E16&F16 -> Ground项目部OG 美南区AT303 | I16: Station Trainee 站点培训生 | O16: / | P16: 0 | Q16: 0 | R16: 0 | S16: =Q16+R16 -> 0 | T16: =IF(S16-8>0,S16-8,0) -> 0 | U16: =IF(T16=0,"否","是") -> 否 | V16: =VLOOKUP($C16,[4]Sheet1!$B:$AN,39,FALSE) -> 0 | W16: 0 | X16: 0 | Y16: 0 | Z16: =IF(Y16-X16>=0,Y16-X16,0) -> 0 | AA16: =IF(J16="","否","是") -> 否 | AC16: =VLOOKUP(C16,[1]Sheet1!$C:$O,13,FALSE) -> #N/A | AD16: =VLOOKUP($H16,'[3]0509人员排班情况 副本'!$G:$U,12,FALSE) -> 王安琪 (Anqi Wang),张朱同 Thomson（Zhutong Zhang） | AE16: =VLOOKUP($H16,'[3]0509人员排班情况 副本'!$G:$U,13,FALSE) -> 陈锦昭 | AF16: =VLOOKUP($H16,'[3]0509人员排班情况 副本'!$G:$U,14,FALSE) -> 金筱燕Sharon（Xiaoyan Jin） | AG16: =VLOOKUP($H16,'[3]0509人员排班情况 副本'!$G:$U,15,FALSE) -> 0
B17: 陈淑茵 Nicole （Shuyin Chen） | C17: GL501463 | D17: MS 中南大区 | E17: CS 夏洛特及周边片区 | F17: CLT02 | H17: =D17&E17&F17 -> MS 中南大区CS 夏洛特及周边片区CLT02 | I17: Station Operations Specialist 站点运营专员 | O17: / | P17: 0 | Q17: 0 | R17: 0 | S17: =Q17+R17 -> 0 | T17: =IF(S17-8>0,S17-8,0) -> 0 | U17: =IF(T17=0,"否","是") -> 否 | V17: =VLOOKUP($C17,[4]Sheet1!$B:$AN,39,FALSE) -> 0 | W17: 0 | X17: 0 | Y17: 0 | Z17: =IF(Y17-X17>=0,Y17-X17,0) -> 0 | AA17: =IF(J17="","否","是") -> 否 | AC17: =VLOOKUP(C17,[1]Sheet1!$C:$O,13,FALSE) -> #N/A | AD17: =VLOOKUP($H17,'[3]0509人员排班情况 副本'!$G:$U,12,FALSE) -> 欧阳迎春Flower（Yingchun Ouyang） | AE17: =VLOOKUP($H17,'[3]0509人员排班情况 副本'!$G:$U,13,FALSE) -> 杨云飞 | AF17: =VLOOKUP($H17,'[3]0509人员排班情况 副本'!$G:$U,14,FALSE) -> 郭丞芸Lexie(Chengyun Kuo) | AG17: =VLOOKUP($H17,'[3]0509人员排班情况 副本'!$G:$U,15,FALSE) -> 0
B18: 陈玥丹Karol（Yuedan Chen） | C18: GL501694 | D18: MS 中南大区 | E18: 运营支持部 | F18: 区域支持组 | H18: =D18&E18&F18 -> MS 中南大区运营支持部区域支持组 | I18: Regional Support Specialist 区域支持专员 | O18: / | P18: 0 | Q18: 0 | R18: 0 | S18: =Q18+R18 -> 0 | T18: =IF(S18-8>0,S18-8,0) -> 0 | U18: =IF(T18=0,"否","是") -> 否 | V18: =VLOOKUP($C18,[4]Sheet1!$B:$AN,39,FALSE) -> 0 | W18: 0 | X18: 0 | Y18: 0 | Z18: =IF(Y18-X18>=0,Y18-X18,0) -> 0 | AA18: =IF(J18="","否","是") -> 否 | AC18: =VLOOKUP(C18,[1]Sheet1!$C:$O,13,FALSE) -> #N/A | AD18: =VLOOKUP($H18,'[3]0509人员排班情况 副本'!$G:$U,12,FALSE) -> 欧阳迎春Flower（Yingchun Ouyang） | AE18: =VLOOKUP($H18,'[3]0509人员排班情况 副本'!$G:$U,13,FALSE) -> 杨云飞 | AF18: =VLOOKUP($H18,'[3]0509人员排班情况 副本'!$G:$U,14,FALSE) -> 0 | AG18: =VLOOKUP($H18,'[3]0509人员排班情况 副本'!$G:$U,15,FALSE) -> 0
A19: 2026/05/12 | B19: Alabran (Alabran Reyes) | C19: GL501448 | D19: FL 佛州大区 | E19: TPA01 | H19: =D19&E19&F19 -> FL 佛州大区TPA01 | I19: Station Operations Specialist 站点运营专员 | J19: TY_04:00 | K19: 0.16666667 | L19: 12:30 | M19: 0.21180556 | N19: 12:06 | O19: 正确 | P19: 0 | Q19: 6.52 | R19: 0 | S19: =Q19+R19 -> 6.52 | T19: =IF(S19-8>0,S19-8,0) -> 0 | U19: =IF(T19=0,"否","是") -> 否 | V19: =VLOOKUP($C19,[4]Sheet1!$B:$AN,39,FALSE) -> 6.52 | W19: 0 | X19: 2 | Y19: 4 | Z19: =IF(Y19-X19>=0,Y19-X19,0) -> 2 | AA19: =IF(J19="","否","是") -> 是 | AC19: =VLOOKUP(C19,[1]Sheet1!$C:$O,13,FALSE) -> #N/A | AD19: =VLOOKUP($H19,'[3]0509人员排班情况 副本'!$G:$U,12,FALSE) -> Natalia (Natalia Padilla),孙婕 Jasmine（Sunjie） | AE19: =VLOOKUP($H19,'[3]0509人员排班情况 副本'!$G:$U,13,FALSE) -> 贺子强Jeff (Ziqiang He) | AF19: =VLOOKUP($H19,'[3]0509人员排班情况 副本'!$G:$U,14,FALSE) -> 0 | AG19: =VLOOKUP($H19,'[3]0509人员排班情况 副本'!$G:$U,15,FALSE) -> 0
A20: 2026/05/12 | B20: Alexis (Alexis Castillo) | C20: GL502454 | D20: FL 佛州大区 | E20: MIA.H | F20: 操作组 | G20: HUB | H20: =D20&E20&F20 -> FL 佛州大区MIA.H操作组 | I20: Warehouse Operator 操作员 | J20: TY_08:00 | K20: 0.33333333 | L20: 16:30 | M20: 0.33958333 | N20: 17:32 | O20: =IFERROR(IF(ABS(M20-K20)<=1/24,"正确","不正确"),"/") -> 正确 | P20: 0 | Q20: 8.88 | R20: 0 | S20: =Q20+R20 -> 8.88 | T20: =IF(S20-8>0,S20-8,0) -> 0.88 | U20: =IF(T20=0,"否","是") -> 是 | V20: =VLOOKUP($C20,[4]Sheet1!$B:$AN,39,FALSE) -> 16.05 | W20: 0 | X20: 4 | Y20: 4 | Z20: =IF(Y20-X20>=0,Y20-X20,0) -> 0 | AA20: =IF(J20="","否","是") -> 是 | AC20: =VLOOKUP(C20,[1]Sheet1!$C:$O,13,FALSE) -> #N/A | AD20: =VLOOKUP($H20,'[3]0509人员排班情况 副本'!$G:$U,12,FALSE) -> Natalia (Natalia Padilla),孙婕 Jasmine（Sunjie） | AE20: =VLOOKUP($H20,'[3]0509人员排班情况 副本'!$G:$U,13,FALSE) -> 贺子强Jeff (Ziqiang He) | AF20: =VLOOKUP($H20,'[3]0509人员排班情况 副本'!$G:$U,14,FALSE) -> Minqing (Minqing Xu),罗煜雄 Mike (Yuxiong Luo) | AG20: =VLOOKUP($H20,'[3]0509人员排班情况 副本'!$G:$U,15,FALSE) -> 0
A21: 2026/05/12 | B21: Alexis Villanueva | C21: GL502827 | D21: TX 德州大区 | E21: GC 墨湾片区 | F21: MFE01 | H21: =D21&E21&F21 -> TX 德州大区GC 墨湾片区MFE01 | I21: Station Operations Specialist 站点运营专员 | J21: TY_休息日 | K21: 0.39583333 | L21: 18:00 | O21: 正确 | P21: 0 | Q21: 0 | R21: 0 | S21: =Q21+R21 -> 0 | T21: =IF(S21-8>0,S21-8,0) -> 0 | U21: =IF(T21=0,"否","是") -> 否 | V21: =VLOOKUP($C21,[4]Sheet1!$B:$AN,39,FALSE) -> 0 | W21: 0 | X21: 0 | Y21: 0 | Z21: =IF(Y21-X21>=0,Y21-X21,0) -> 0 | AA21: =IF(J21="","否","是") -> 是 | AC21: =VLOOKUP(C21,[1]Sheet1!$C:$O,13,FALSE) -> #N/A | AD21: =VLOOKUP($H21,'[3]0509人员排班情况 副本'!$G:$U,12,FALSE) -> 肖芦莉Lily (Luli Xiao) | AE21: =VLOOKUP($H21,'[3]0509人员排班情况 副本'!$G:$U,13,FALSE) -> 张骥Ji Zhang (Ji Zhang) | AF21: =VLOOKUP($H21,'[3]0509人员排班情况 副本'!$G:$U,14,FALSE) -> 金磊Brian（LEI JIN） | AG21: =VLOOKUP($H21,'[3]0509人员排班情况 副本'!$G:$U,15,FALSE) -> 0
A22: 2026/05/12 | B22: Alfaro, Walter Jessie（Alfaro, Walter Jessie） | C22: GL500434 | D22: WE 美西大区 | E22: LAV.H | F22: 操作组 | G22: HUB | H22: =D22&E22&F22 -> WE 美西大区LAV.H操作组 | I22: Warehouse Operator 操作员 | J22: TY_05:00 | K22: 0.20833333 | L22: 13:30 | O22: =IFERROR(IF(ABS(M22-K22)<=1/24,"正确","不正确"),"/") -> 不正确 | P22: 0 | Q22: 0 | R22: 0 | S22: =Q22+R22 -> 0 | T22: =IF(S22-8>0,S22-8,0) -> 0 | U22: =IF(T22=0,"否","是") -> 否 | V22: =VLOOKUP($C22,[4]Sheet1!$B:$AN,39,FALSE) -> 0 | W22: 0 | X22: 0 | Y22: 0 | Z22: =IF(Y22-X22>=0,Y22-X22,0) -> 0 | AA22: =IF(J22="","否","是") -> 是 | AB22: 年假2026/05/12 06:00-2026/05/12 14:30[已完成] | AC22: =VLOOKUP(C22,[1]Sheet1!$C:$O,13,FALSE) -> #N/A | AD22: =VLOOKUP($H22,'[3]0509人员排班情况 副本'!$G:$U,12,FALSE) -> 王骞Ariel（Qian Wang）,叶秀芳Freya (Xiufang Ye) | AE22: =VLOOKUP($H22,'[3]0509人员排班情况 副本'!$G:$U,13,FALSE) -> 常哲 | AF22: =VLOOKUP($H22,'[3]0509人员排班情况 副本'!$G:$U,14,FALSE) -> Minqing (Minqing Xu),罗煜雄 Mike (Yuxiong Luo) | AG22: =VLOOKUP($H22,'[3]0509人员排班情况 副本'!$G:$U,15,FALSE) -> 0
A23: 2026/05/12 | B23: Andrea （Andrea Silva） | C23: GL501635 | D23: FL 佛州大区 | E23: MIA.H | F23: 操作组 | G23: HUB | H23: =D23&E23&F23 -> FL 佛州大区MIA.H操作组 | I23: Warehouse Operator 操作员 | J23: TY_休息日 | K23: 0.39583333 | L23: 18:00 | O23: 正确 | P23: 0 | Q23: 0 | R23: 0 | S23: =Q23+R23 -> 0 | T23: =IF(S23-8>0,S23-8,0) -> 0 | U23: =IF(T23=0,"否","是") -> 否 | V23: =VLOOKUP($C23,[4]Sheet1!$B:$AN,39,FALSE) -> 0 | W23: 0 | X23: 0 | Y23: 0 | Z23: =IF(Y23-X23>=0,Y23-X23,0) -> 0 | AA23: =IF(J23="","否","是") -> 是 | AC23: =VLOOKUP(C23,[1]Sheet1!$C:$O,13,FALSE) -> #N/A | AD23: =VLOOKUP($H23,'[3]0509人员排班情况 副本'!$G:$U,12,FALSE) -> Natalia (Natalia Padilla),孙婕 Jasmine（Sunjie） | AE23: =VLOOKUP($H23,'[3]0509人员排班情况 副本'!$G:$U,13,FALSE) -> 贺子强Jeff (Ziqiang He) | AF23: =VLOOKUP($H23,'[3]0509人员排班情况 副本'!$G:$U,14,FALSE) -> Minqing (Minqing Xu),罗煜雄 Mike (Yuxiong Luo) | AG23: =VLOOKUP($H23,'[3]0509人员排班情况 副本'!$G:$U,15,FALSE) -> 0
A24: 2026/05/12 | B24: Andrea(Andrea Velez) | C24: GL500972 | D24: MS 中南大区 | E24: AS 亚特兰大和南阿拉巴马片区 | F24: ATL01 | H24: =D24&E24&F24 -> MS 中南大区AS 亚特兰大和南阿拉巴马片区ATL01 | I24: Warehouse Operator 操作员 | J24: TY_06:30 | K24: 0.27083333 | L24: 15:00 | M24: 0.27430556 | N24: 14:50 | O24: =IFERROR(IF(ABS(M24-K24)<=1/24,"正确","不正确"),"/") -> 正确 | P24: 0 | Q24: 7.75 | R24: 0 | S24: =Q24+R24 -> 7.75 | T24: =IF(S24-8>0,S24-8,0) -> 0 | U24: =IF(T24=0,"否","是") -> 否 | V24: =VLOOKUP($C24,[4]Sheet1!$B:$AN,39,FALSE) -> 15.97 | W24: 0 | X24: 4 | Y24: 4 | Z24: =IF(Y24-X24>=0,Y24-X24,0) -> 0 | AA24: =IF(J24="","否","是") -> 是 | AC24: =VLOOKUP(C24,[1]Sheet1!$C:$O,13,FALSE) -> #N/A | AD24: =VLOOKUP($H24,'[3]0509人员排班情况 副本'!$G:$U,12,FALSE) -> 欧阳迎春Flower（Yingchun Ouyang） | AE24: =VLOOKUP($H24,'[3]0509人员排班情况 副本'!$G:$U,13,FALSE) -> 杨云飞 | AF24: =VLOOKUP($H24,'[3]0509人员排班情况 副本'!$G:$U,14,FALSE) -> 李明峰Lucas(Mingfeng Li) | AG24: =VLOOKUP($H24,'[3]0509人员排班情况 副本'!$G:$U,15,FALSE) -> 0
A25: 2026/05/12 | B25: Andrew Michael Garcia | C25: GL502227 | D25: BD 本地客户部 | E25: 客服组 | H25: =D25&E25&F25 -> BD 本地客户部客服组 | I25: Customer Service Specialist 客服专员 | J25: TY_09:30 | K25: 0.39583333 | L25: 18:00 | O25: =IFERROR(IF(ABS(M25-K25)<=1/24,"正确","不正确"),"/") -> 不正确 | P25: 0 | Q25: 0 | R25: 0 | S25: =Q25+R25 -> 0 | T25: =IF(S25-8>0,S25-8,0) -> 0 | U25: =IF(T25=0,"否","是") -> 否 | V25: =VLOOKUP($C25,[4]Sheet1!$B:$AN,39,FALSE) -> 0 | W25: 0 | X25: 0 | Y25: 4 | Z25: =IF(Y25-X25>=0,Y25-X25,0) -> 4 | AA25: =IF(J25="","否","是") -> 是 | AC25: =VLOOKUP(C25,[1]Sheet1!$C:$O,13,FALSE) -> #N/A | AD25: =VLOOKUP($H25,'[3]0509人员排班情况 副本'!$G:$U,12,FALSE) -> 袁博闻(Bowen Yuan) | AE25: =VLOOKUP($H25,'[3]0509人员排班情况 副本'!$G:$U,13,FALSE) -> 0 | AF25: =VLOOKUP($H25,'[3]0509人员排班情况 副本'!$G:$U,14,FALSE) -> 0 | AG25: =VLOOKUP($H25,'[3]0509人员排班情况 副本'!$G:$U,15,FALSE) -> 0
A26: 2026/05/12 | B26: Annie Wang | C26: GL501231 | D26: AS 审计监察部 | H26: =D26&E26&F26 -> AS 审计监察部 | I26: Senior Overseas Audit Manager 高级海外审计经理 | J26: TY_09:30 | K26: 0.39583333 | L26: 18:00 | M26: 0.39583333 | N26: 18:00 | O26: =IFERROR(IF(ABS(M26-K26)<=1/24,"正确","不正确"),"/") -> 正确 | P26: 0 | Q26: 8 | R26: 0 | S26: =Q26+R26 -> 8 | T26: =IF(S26-8>0,S26-8,0) -> 0 | U26: =IF(T26=0,"否","是") -> 否 | V26: =VLOOKUP($C26,[4]Sheet1!$B:$AN,39,FALSE) -> 16 | W26: 0 | X26: 2 | Y26: 0 | Z26: =IF(Y26-X26>=0,Y26-X26,0) -> 0 | AA26: =IF(J26="","否","是") -> 是 | AB26: 年假2026/05/12 09:30-2026/05/12 18:00[已完成] | AC26: =VLOOKUP(C26,[1]Sheet1!$C:$O,13,FALSE) -> #N/A | AD26: =VLOOKUP($H26,'[3]0509人员排班情况 副本'!$G:$U,12,FALSE) -> 袁博闻(Bowen Yuan) | AE26: =VLOOKUP($H26,'[3]0509人员排班情况 副本'!$G:$U,13,FALSE) -> 0 | AF26: =VLOOKUP($H26,'[3]0509人员排班情况 副本'!$G:$U,14,FALSE) -> 0 | AG26: =VLOOKUP($H26,'[3]0509人员排班情况 副本'!$G:$U,15,FALSE) -> 0
A27: 2026/05/12 | B27: Antonio (Antonio Yong Liang) | C27: GL502356 | D27: FL 佛州大区 | E27: MIA.H | F27: 调度组 | G27: HUB | H27: =D27&E27&F27 -> FL 佛州大区MIA.H调度组 | I27: Dispatch Lead 调度组长 | J27: TY_18:00 | K27: 0.75 | L27: 02:30 | M27: 0.74583333 | O27: =IFERROR(IF(ABS(M27-K27)<=1/24,"正确","不正确"),"/") -> 正确 | P27: 0 | Q27: 0 | R27: 0 | S27: =Q27+R27 -> 0 | T27: =IF(S27-8>0,S27-8,0) -> 0 | U27: =IF(T27=0,"否","是") -> 否 | V27: =VLOOKUP($C27,[4]Sheet1!$B:$AN,39,FALSE) -> 9.78 | W27: 0 | X27: 1 | Y27: 4 | Z27: =IF(Y27-X27>=0,Y27-X27,0) -> 3 | AA27: =IF(J27="","否","是") -> 是 | AC27: =VLOOKUP(C27,[1]Sheet1!$C:$O,13,FALSE) -> #N/A | AD27: =VLOOKUP($H27,'[3]0509人员排班情况 副本'!$G:$U,12,FALSE) -> Natalia (Natalia Padilla),孙婕 Jasmine（Sunjie） | AE27: =VLOOKUP($H27,'[3]0509人员排班情况 副本'!$G:$U,13,FALSE) -> 贺子强Jeff (Ziqiang He) | AF27: =VLOOKUP($H27,'[3]0509人员排班情况 副本'!$G:$U,14,FALSE) -> Minqing (Minqing Xu),罗煜雄 Mike (Yuxiong Luo) | AG27: =VLOOKUP($H27,'[3]0509人员排班情况 副本'!$G:$U,15,FALSE) -> 0
A28: 2026/05/12 | B28: Arielle (Arielle Ho) | C28: GL500334 | D28: FL 佛州大区 | E28: MIA.H | F28: 调度组 | G28: HUB | H28: =D28&E28&F28 -> FL 佛州大区MIA.H调度组 | I28: Dispatch Lead 调度组长 | J28: TY_11:00 | K28: 0.45833333 | L28: 19:30 | M28: 0.44652778 | N28: 21:33 | O28: =IFERROR(IF(ABS(M28-K28)<=1/24,"正确","不正确"),"/") -> 正确 | P28: 0 | Q28: 10.33 | R28: 0 | S28: =Q28+R28 -> 10.33 | T28: =IF(S28-8>0,S28-8,0) -> 2.33 | U28: =IF(T28=0,"否","是") -> 是 | V28: =VLOOKUP($C28,[4]Sheet1!$B:$AN,39,FALSE) -> 20.25 | W28: 0 | X28: 3 | Y28: 4 | Z28: =IF(Y28-X28>=0,Y28-X28,0) -> 1 | AA28: =IF(J28="","否","是") -> 是 | AC28: =VLOOKUP(C28,[1]Sheet1!$C:$O,13,FALSE) -> #N/A | AD28: =VLOOKUP($H28,'[3]0509人员排班情况 副本'!$G:$U,12,FALSE) -> Natalia (Natalia Padilla),孙婕 Jasmine（Sunjie） | AE28: =VLOOKUP($H28,'[3]0509人员排班情况 副本'!$G:$U,13,FALSE) -> 贺子强Jeff (Ziqiang He) | AF28: =VLOOKUP($H28,'[3]0509人员排班情况 副本'!$G:$U,14,FALSE) -> Minqing (Minqing Xu),罗煜雄 Mike (Yuxiong Luo) | AG28: =VLOOKUP($H28,'[3]0509人员排班情况 副本'!$G:$U,15,FALSE) -> 0
A29: 2026/05/12 | B29: Ben(Neng Xiong) | C29: GL502559 | D29: MS 中南大区 | E29: CLT.H | F29: 操作组 | G29: HUB | H29: =D29&E29&F29 -> MS 中南大区CLT.H操作组 | I29: Warehouse Operator 操作员 | J29: TY_08:00 | K29: 0.33333333 | L29: 16:30 | M29: 0.33958333 | N29: 17:00 | O29: =IFERROR(IF(ABS(M29-K29)<=1/24,"正确","不正确"),"/") -> 正确 | P29: 0 | Q29: 8.35 | R29: 0 | S29: =Q29+R29 -> 8.35 | T29: =IF(S29-8>0,S29-8,0) -> 0.35 | U29: =IF(T29=0,"否","是") -> 是 | V29: =VLOOKUP($C29,[4]Sheet1!$B:$AN,39,FALSE) -> 17.42 | W29: 0 | X29: 2 | Y29: 4 | Z29: =IF(Y29-X29>=0,Y29-X29,0) -> 2 | AA29: =IF(J29="","否","是") -> 是 | AC29: =VLOOKUP(C29,[1]Sheet1!$C:$O,13,FALSE) -> #N/A | AD29: =VLOOKUP($H29,'[3]0509人员排班情况 副本'!$G:$U,12,FALSE) -> 欧阳迎春Flower（Yingchun Ouyang） | AE29: =VLOOKUP($H29,'[3]0509人员排班情况 副本'!$G:$U,13,FALSE) -> 杨云飞 | AF29: =VLOOKUP($H29,'[3]0509人员排班情况 副本'!$G:$U,14,FALSE) -> Minqing (Minqing Xu),罗煜雄 Mike (Yuxiong Luo) | AG29: =VLOOKUP($H29,'[3]0509人员排班情况 副本'!$G:$U,15,FALSE) -> 0
A30: 2026/05/12 | B30: Benjamin Alejandro Zendejas | C30: GL502177 | D30: WE 美西大区 | E30: SC 南加片区 | F30: FAT01 | H30: =D30&E30&F30 -> WE 美西大区SC 南加片区FAT01 | I30: Station Operations Specialist 站点运营专员 | J30: TY_04:30 | K30: 0.1875 | L30: 13:00 | M30: 0.18680556 | N30: 13:00 | O30: =IFERROR(IF(ABS(M30-K30)<=1/24,"正确","不正确"),"/") -> 正确 | P30: 0 | Q30: 8.02 | R30: 0 | S30: =Q30+R30 -> 8.02 | T30: =IF(S30-8>0,S30-8,0) -> 0.02 | U30: =IF(T30=0,"否","是") -> 是 | V30: =VLOOKUP($C30,[4]Sheet1!$B:$AN,39,FALSE) -> 16.07 | W30: 0 | X30: 4 | Y30: 4 | Z30: =IF(Y30-X30>=0,Y30-X30,0) -> 0 | AA30: =IF(J30="","否","是") -> 是 | AC30: =VLOOKUP(C30,[1]Sheet1!$C:$O,13,FALSE) -> #N/A | AD30: =VLOOKUP($H30,'[3]0509人员排班情况 副本'!$G:$U,12,FALSE) -> 王骞Ariel（Qian Wang）,叶秀芳Freya (Xiufang Ye) | AE30: =VLOOKUP($H30,'[3]0509人员排班情况 副本'!$G:$U,13,FALSE) -> 常哲 | AF30: =VLOOKUP($H30,'[3]0509人员排班情况 副本'!$G:$U,14,FALSE) -> 尤梦楠Yuko（Mengnan You） | AG30: =VLOOKUP($H30,'[3]0509人员排班情况 副本'!$G:$U,15,FALSE) -> 0
A31: 2026/05/12 | B31: Ben苏国邦（Ben Su） | C31: GL502562 | D31: TX 德州大区 | E31: NT 北德州片区 | F31: DFW01 | H31: =D31&E31&F31 -> TX 德州大区NT 北德州片区DFW01 | I31: Station Operations Specialist 站点运营专员 | J31: TY_休息日 | K31: 0.39583333 | L31: 18:00 | O31: 正确 | P31: 0 | Q31: 0 | R31: 0 | S31: =Q31+R31 -> 0 | T31: =IF(S31-8>0,S31-8,0) -> 0 | U31: =IF(T31=0,"否","是") -> 否 | V31: =VLOOKUP($C31,[4]Sheet1!$B:$AN,39,FALSE) -> 0 | W31: 0 | X31: 0 | Y31: 0 | Z31: =IF(Y31-X31>=0,Y31-X31,0) -> 0 | AA31: =IF(J31="","否","是") -> 是 | AC31: =VLOOKUP(C31,[1]Sheet1!$C:$O,13,FALSE) -> #N/A | AD31: =VLOOKUP($H31,'[3]0509人员排班情况 副本'!$G:$U,12,FALSE) -> 肖芦莉Lily (Luli Xiao) | AE31: =VLOOKUP($H31,'[3]0509人员排班情况 副本'!$G:$U,13,FALSE) -> 张骥Ji Zhang (Ji Zhang) | AF31: =VLOOKUP($H31,'[3]0509人员排班情况 副本'!$G:$U,14,FALSE) -> 何琼joan(Qiong He) | AG31: =VLOOKUP($H31,'[3]0509人员排班情况 副本'!$G:$U,15,FALSE) -> 0
A32: 2026/05/12 | B32: Bobby Barry | C32: GL502239 | D32: BD 本地客户部 | E32: 北美销售组 | H32: =D32&E32&F32 -> BD 本地客户部北美销售组 | I32: Sales Supervisor 销售主管 | J32: TY_09:30 | K32: 0.39583333 | L32: 18:00 | O32: =IFERROR(IF(ABS(M32-K32)<=1/24,"正确","不正确"),"/") -> 不正确 | P32: 0 | Q32: 0 | R32: 0 | S32: =Q32+R32 -> 0 | T32: =IF(S32-8>0,S32-8,0) -> 0 | U32: =IF(T32=0,"否","是") -> 否 | V32: =VLOOKUP($C32,[4]Sheet1!$B:$AN,39,FALSE) -> 0 | W32: 0 | X32: 0 | Y32: 4 | Z32: =IF(Y32-X32>=0,Y32-X32,0) -> 4 | AA32: =IF(J32="","否","是") -> 是 | AC32: =VLOOKUP(C32,[1]Sheet1!$C:$O,13,FALSE) -> #N/A | AD32: =VLOOKUP($H32,'[3]0509人员排班情况 副本'!$G:$U,12,FALSE) -> 袁博闻(Bowen Yuan) | AE32: =VLOOKUP($H32,'[3]0509人员排班情况 副本'!$G:$U,13,FALSE) -> 0 | AF32: =VLOOKUP($H32,'[3]0509人员排班情况 副本'!$G:$U,14,FALSE) -> 0 | AG32: =VLOOKUP($H32,'[3]0509人员排班情况 副本'!$G:$U,15,FALSE) -> 0
A33: 2026/05/12 | B33: Cameron Tabatabaei Roudsari | C33: GL502241 | D33: BD 本地客户部 | E33: 北美销售组 | H33: =D33&E33&F33 -> BD 本地客户部北美销售组 | I33: Sales Supervisor 销售主管 | J33: TY_09:30 | K33: 0.39583333 | L33: 18:00 | O33: =IFERROR(IF(ABS(M33-K33)<=1/24,"正确","不正确"),"/") -> 不正确 | P33: 0 | Q33: 0 | R33: 0 | S33: =Q33+R33 -> 0 | T33: =IF(S33-8>0,S33-8,0) -> 0 | U33: =IF(T33=0,"否","是") -> 否 | V33: =VLOOKUP($C33,[4]Sheet1!$B:$AN,39,FALSE) -> 0 | W33: 0 | X33: 0 | Y33: 4 | Z33: =IF(Y33-X33>=0,Y33-X33,0) -> 4 | AA33: =IF(J33="","否","是") -> 是 | AC33: =VLOOKUP(C33,[1]Sheet1!$C:$O,13,FALSE) -> #N/A | AD33: =VLOOKUP($H33,'[3]0509人员排班情况 副本'!$G:$U,12,FALSE) -> 袁博闻(Bowen Yuan) | AE33: =VLOOKUP($H33,'[3]0509人员排班情况 副本'!$G:$U,13,FALSE) -> 0 | AF33: =VLOOKUP($H33,'[3]0509人员排班情况 副本'!$G:$U,14,FALSE) -> 0 | AG33: =VLOOKUP($H33,'[3]0509人员排班情况 副本'!$G:$U,15,FALSE) -> 0
A34: 2026/05/12 | B34: Canzhe Tang | C34: GL502245 | D34: BD 本地客户部 | E34: 加拿大运营组 | H34: =D34&E34&F34 -> BD 本地客户部加拿大运营组 | I34: Junior Operations Support Specialist 初级运营支持专员 | J34: TY_09:30 | K34: 0.39583333 | L34: 18:00 | O34: =IFERROR(IF(ABS(M34-K34)<=1/24,"正确","不正确"),"/") -> 不正确 | P34: 0 | Q34: 0 | R34: 0 | S34: =Q34+R34 -> 0 | T34: =IF(S34-8>0,S34-8,0) -> 0 | U34: =IF(T34=0,"否","是") -> 否 | V34: =VLOOKUP($C34,[4]Sheet1!$B:$AN,39,FALSE) -> 0 | W34: 0 | X34: 0 | Y34: 4 | Z34: =IF(Y34-X34>=0,Y34-X34,0) -> 4 | AA34: =IF(J34="","否","是") -> 是 | AC34: =VLOOKUP(C34,[1]Sheet1!$C:$O,13,FALSE) -> #N/A | AD34: =VLOOKUP($H34,'[3]0509人员排班情况 副本'!$G:$U,12,FALSE) -> 袁博闻(Bowen Yuan) | AE34: =VLOOKUP($H34,'[3]0509人员排班情况 副本'!$G:$U,13,FALSE) -> 0 | AF34: =VLOOKUP($H34,'[3]0509人员排班情况 副本'!$G:$U,14,FALSE) -> 0 | AG34: =VLOOKUP($H34,'[3]0509人员排班情况 副本'!$G:$U,15,FALSE) -> 0
A35: 2026/05/12 | B35: Cao Yijin (Yijin Cao) | C35: GL500938 | D35: FL 佛州大区 | E35: MCO.H | F35: 分拣组 | G35: HUB | H35: =D35&E35&F35 -> FL 佛州大区MCO.H分拣组 | I35: Sorting Lead 分拣组长 | J35: TY_休息日 | K35: 0.39583333 | L35: 18:00 | O35: 正确 | P35: 0 | Q35: 0 | R35: 0 | S35: =Q35+R35 -> 0 | T35: =IF(S35-8>0,S35-8,0) -> 0 | U35: =IF(T35=0,"否","是") -> 否 | V35: =VLOOKUP($C35,[4]Sheet1!$B:$AN,39,FALSE) -> 15.75 | W35: 34.97 | X35: 0 | Y35: 0 | Z35: =IF(Y35-X35>=0,Y35-X35,0) -> 0 | AA35: =IF(J35="","否","是") -> 是 | AC35: =VLOOKUP(C35,[1]Sheet1!$C:$O,13,FALSE) -> #N/A | AD35: =VLOOKUP($H35,'[3]0509人员排班情况 副本'!$G:$U,12,FALSE) -> Natalia (Natalia Padilla),孙婕 Jasmine（Sunjie） | AE35: =VLOOKUP($H35,'[3]0509人员排班情况 副本'!$G:$U,13,FALSE) -> 贺子强Jeff (Ziqiang He) | AF35: =VLOOKUP($H35,'[3]0509人员排班情况 副本'!$G:$U,14,FALSE) -> 张双甫(Shuangfu Zhang) | AG35: =VLOOKUP($H35,'[3]0509人员排班情况 副本'!$G:$U,15,FALSE) -> 0
A36: 2026/05/12 | B36: Chad Emerson | C36: GL502240 | D36: BD 本地客户部 | E36: 北美销售组 | H36: =D36&E36&F36 -> BD 本地客户部北美销售组 | I36: Sales Supervisor 销售主管 | J36: TY_09:30 | K36: 0.39583333 | L36: 18:00 | O36: =IFERROR(IF(ABS(M36-K36)<=1/24,"正确","不正确"),"/") -> 不正确 | P36: 0 | Q36: 0 | R36: 0 | S36: =Q36+R36 -> 0 | T36: =IF(S36-8>0,S36-8,0) -> 0 | U36: =IF(T36=0,"否","是") -> 否 | V36: =VLOOKUP($C36,[4]Sheet1!$B:$AN,39,FALSE) -> 0 | W36: 0 | X36: 0 | Y36: 4 | Z36: =IF(Y36-X36>=0,Y36-X36,0) -> 4 | AA36: =IF(J36="","否","是") -> 是 | AC36: =VLOOKUP(C36,[1]Sheet1!$C:$O,13,FALSE) -> #N/A | AD36: =VLOOKUP($H36,'[3]0509人员排班情况 副本'!$G:$U,12,FALSE) -> 袁博闻(Bowen Yuan) | AE36: =VLOOKUP($H36,'[3]0509人员排班情况 副本'!$G:$U,13,FALSE) -> 0 | AF36: =VLOOKUP($H36,'[3]0509人员排班情况 副本'!$G:$U,14,FALSE) -> 0 | AG36: =VLOOKUP($H36,'[3]0509人员排班情况 副本'!$G:$U,15,FALSE) -> 0
A37: 2026/05/12 | B37: Chavez William（Chavez William） | C37: GL500500 | D37: WE 美西大区 | E37: LAV.H | F37: 操作组 | G37: HUB | H37: =D37&E37&F37 -> WE 美西大区LAV.H操作组 | I37: Warehouse Lead 操作组长 | J37: TY_10:00 | K37: 0.41666667 | L37: 18:30 | N37: 19:19 | O37: =IFERROR(IF(ABS(M37-K37)<=1/24,"正确","不正确"),"/") -> 不正确 | P37: 0 | Q37: 0 | R37: 0 | S37: =Q37+R37 -> 0 | T37: =IF(S37-8>0,S37-8,0) -> 0 | U37: =IF(T37=0,"否","是") -> 否 | V37: =VLOOKUP($C37,[4]Sheet1!$B:$AN,39,FALSE) -> 0 | W37: 0 | X37: 3 | Y37: 4 | Z37: =IF(Y37-X37>=0,Y37-X37,0) -> 1 | AA37: =IF(J37="","否","是") -> 是 | AC37: =VLOOKUP(C37,[1]Sheet1!$C:$O,13,FALSE) -> #N/A | AD37: =VLOOKUP($H37,'[3]0509人员排班情况 副本'!$G:$U,12,FALSE) -> 王骞Ariel（Qian Wang）,叶秀芳Freya (Xiufang Ye) | AE37: =VLOOKUP($H37,'[3]0509人员排班情况 副本'!$G:$U,13,FALSE) -> 常哲 | AF37: =VLOOKUP($H37,'[3]0509人员排班情况 副本'!$G:$U,14,FALSE) -> Minqing (Minqing Xu),罗煜雄 Mike (Yuxiong Luo) | AG37: =VLOOKUP($H37,'[3]0509人员排班情况 副本'!$G:$U,15,FALSE) -> 0
A38: 2026/05/12 | B38: Cristobal Ybarra（Cristobal） | C38: GL502172 | D38: WE 美西大区 | E38: DS 丹佛·盐湖城片区 | F38: ABQ01 | H38: =D38&E38&F38 -> WE 美西大区DS 丹佛·盐湖城片区ABQ01 | I38: Station Operations Specialist 站点运营专员 | J38: TY_05:00 | K38: 0.20833333 | L38: 13:30 | M38: 0.32847222 | N38: 18:29 | O38: =IFERROR(IF(ABS(M38-K38)<=1/24,"正确","不正确"),"/") -> 不正确 | P38: 0 | Q38: 10.1 | R38: 0 | S38: =Q38+R38 -> 10.1 | T38: =IF(S38-8>0,S38-8,0) -> 2.1 | U38: =IF(T38=0,"否","是") -> 是 | V38: =VLOOKUP($C38,[4]Sheet1!$B:$AN,39,FALSE) -> 22.75 | W38: 0 | X38: 2 | Y38: 4 | Z38: =IF(Y38-X38>=0,Y38-X38,0) -> 2 | AA38: =IF(J38="","否","是") -> 是 | AC38: =VLOOKUP(C38,[1]Sheet1!$C:$O,13,FALSE) -> #N/A | AD38: =VLOOKUP($H38,'[3]0509人员排班情况 副本'!$G:$U,12,FALSE) -> 王骞Ariel（Qian Wang）,叶秀芳Freya (Xiufang Ye) | AE38: =VLOOKUP($H38,'[3]0509人员排班情况 副本'!$G:$U,13,FALSE) -> 常哲 | AF38: =VLOOKUP($H38,'[3]0509人员排班情况 副本'!$G:$U,14,FALSE) -> 兰鹏Peng（Peng Lan） | AG38: =VLOOKUP($H38,'[3]0509人员排班情况 副本'!$G:$U,15,FALSE) -> 0
A39: 2026/05/12 | B39: Daniel Z Rodriguez（Daniel Z Rodriguez） | C39: GL500389 | D39: WE 美西大区 | E39: SC 南加片区 | F39: SFV01 | H39: =D39&E39&F39 -> WE 美西大区SC 南加片区SFV01 | I39: Warehouse Operator 操作员 | J39: TY_04:00 | K39: 0.16666667 | L39: 12:30 | N39: 11:37 | O39: =IFERROR(IF(ABS(M39-K39)<=1/24,"正确","不正确"),"/") -> 不正确 | P39: 0 | Q39: 0 | R39: 0 | S39: =Q39+R39 -> 0 | T39: =IF(S39-8>0,S39-8,0) -> 0 | U39: =IF(T39=0,"否","是") -> 否 | V39: =VLOOKUP($C39,[4]Sheet1!$B:$AN,39,FALSE) -> 0 | W39: 0 | X39: 1 | Y39: 4 | Z39: =IF(Y39-X39>=0,Y39-X39,0) -> 3 | AA39: =IF(J39="","否","是") -> 是 | AC39: =VLOOKUP(C39,[1]Sheet1!$C:$O,13,FALSE) -> #N/A | AD39: =VLOOKUP($H39,'[3]0509人员排班情况 副本'!$G:$U,12,FALSE) -> 王骞Ariel（Qian Wang）,叶秀芳Freya (Xiufang Ye) | AE39: =VLOOKUP($H39,'[3]0509人员排班情况 副本'!$G:$U,13,FALSE) -> 常哲 | AF39: =VLOOKUP($H39,'[3]0509人员排班情况 副本'!$G:$U,14,FALSE) -> 尤梦楠Yuko（Mengnan You） | AG39: =VLOOKUP($H39,'[3]0509人员排班情况 副本'!$G:$U,15,FALSE) -> 0
A40: 2026/05/12 | B40: Darryl (Darryl Reyes Cruz) | C40: GL501561 | D40: FL 佛州大区 | E40: MCO.H | F40: 操作组 | G40: HUB | H40: =D40&E40&F40 -> FL 佛州大区MCO.H操作组 | I40: Warehouse Operator 操作员 | J40: TY_09:00 | K40: 0.375 | L40: 17:30 | O40: =IFERROR(IF(ABS(M40-K40)<=1/24,"正确","不正确"),"/") -> 不正确 | P40: 0 | Q40: 0 | R40: 0 | S40: =Q40+R40 -> 0 | T40: =IF(S40-8>0,S40-8,0) -> 0 | U40: =IF(T40=0,"否","是") -> 否 | V40: =VLOOKUP($C40,[4]Sheet1!$B:$AN,39,FALSE) -> 0 | W40: 0 | X40: 0 | Y40: 0 | Z40: =IF(Y40-X40>=0,Y40-X40,0) -> 0 | AA40: =IF(J40="","否","是") -> 是 | AB40: 病假2026/05/12 09:00-2026/05/12 17:30[已完成] | AC40: =VLOOKUP(C40,[1]Sheet1!$C:$O,13,FALSE) -> #N/A | AD40: =VLOOKUP($H40,'[3]0509人员排班情况 副本'!$G:$U,12,FALSE) -> Natalia (Natalia Padilla),孙婕 Jasmine（Sunjie） | AE40: =VLOOKUP($H40,'[3]0509人员排班情况 副本'!$G:$U,13,FALSE) -> 贺子强Jeff (Ziqiang He) | AF40: =VLOOKUP($H40,'[3]0509人员排班情况 副本'!$G:$U,14,FALSE) -> Minqing (Minqing Xu),罗煜雄 Mike (Yuxiong Luo) | AG40: =VLOOKUP($H40,'[3]0509人员排班情况 副本'!$G:$U,15,FALSE) -> 0
...

Sheet 汇总
A1: 区域 | B1: 部门 | C1: 区域 | D1: 0512美区正式工未排班及缺卡人员明细 | K1: 0511美区正式工未排班及缺卡人员明细 | M1: 前一日趋势对比
D2: 总人数 | E2: 日超8h人数 | F2: 未排班数 | G2: 排班率 | H2: HUB排班正确率 | I2: 缺卡数 | J2: 缺卡率 | K2: 排班率 | L2: 缺卡率 | M2: 排班率 | N2: 缺卡率
A3: FL 佛州大区 | B3: SF 南佛片区 | C3: =A3&""&B3 -> FL 佛州大区SF 南佛片区 | D3: =VLOOKUP($C3,是否排班!$I:$L,4,FALSE) -> 10 | E3: =VLOOKUP($C3,日超8H!$I:$L,2,FALSE) -> 4 | F3: =VLOOKUP($C3,是否排班!$I:$L,3,FALSE) -> 1 | G3: =VLOOKUP($C3,是否排班!$I:$M,5,FALSE) -> 0.9 | H3: =IFERROR(VLOOKUP($C3,排班正确!$J:$O,6,FALSE),"/") -> / | I3: =VLOOKUP($C3,缺卡!$H:$K,2,FALSE) -> 6 | J3: =VLOOKUP($C3,缺卡!$H:$K,4,FALSE) -> 0.25 | K3: =VLOOKUP($C3,[2]汇总!$C:$J,5,FALSE) -> 0.9 | L3: =VLOOKUP($C3,[2]汇总!$C:$J,8,FALSE) -> 0.4 | M3: =G3-K3 -> 0 | N3: =J3-L3 -> -0.15
A4: FL 佛州大区 | B4: MIA.H | C4: =A4&""&B4 -> FL 佛州大区MIA.H | D4: =VLOOKUP($C4,是否排班!$I:$L,4,FALSE) -> 34 | E4: =VLOOKUP($C4,日超8H!$I:$L,2,FALSE) -> 17 | F4: =VLOOKUP($C4,是否排班!$I:$L,3,FALSE) -> 1 | G4: =VLOOKUP($C4,是否排班!$I:$M,5,FALSE) -> 0.97058824 | H4: =IFERROR(VLOOKUP($C4,排班正确!$J:$O,6,FALSE),"/") -> 0.76470588 | I4: =VLOOKUP($C4,缺卡!$H:$K,2,FALSE) -> 38 | J4: =VLOOKUP($C4,缺卡!$H:$K,4,FALSE) -> 0.33928571 | K4: =VLOOKUP($C4,[2]汇总!$C:$J,5,FALSE) -> 0.97142857 | L4: =VLOOKUP($C4,[2]汇总!$C:$J,8,FALSE) -> 0.59375 | M4: =G4-K4 -> -0.00084033613 | N4: =J4-L4 -> -0.25446429
A5: FL 佛州大区 | C5: =A5&""&B5 -> FL 佛州大区 | D5: =VLOOKUP($C5,是否排班!$I:$L,4,FALSE) -> 1 | E5: =VLOOKUP($C5,日超8H!$I:$L,2,FALSE) -> 0 | F5: =VLOOKUP($C5,是否排班!$I:$L,3,FALSE) -> 0 | G5: =VLOOKUP($C5,是否排班!$I:$M,5,FALSE) -> 1 | H5: =IFERROR(VLOOKUP($C5,排班正确!$J:$O,6,FALSE),"/") -> / | I5: =VLOOKUP($C5,缺卡!$H:$K,2,FALSE) -> 2 | J5: =VLOOKUP($C5,缺卡!$H:$K,4,FALSE) -> 0.5 | K5: =VLOOKUP($C5,[2]汇总!$C:$J,5,FALSE) -> 1 | L5: =VLOOKUP($C5,[2]汇总!$C:$J,8,FALSE) -> 0.5 | M5: =G5-K5 -> 0 | N5: =J5-L5 -> 0
A6: FL 佛州大区 | B6: FTM01 | C6: =A6&""&B6 -> FL 佛州大区FTM01 | D6: =VLOOKUP($C6,是否排班!$I:$L,4,FALSE) -> 3 | E6: =VLOOKUP($C6,日超8H!$I:$L,2,FALSE) -> 0 | F6: =VLOOKUP($C6,是否排班!$I:$L,3,FALSE) -> 0 | G6: =VLOOKUP($C6,是否排班!$I:$M,5,FALSE) -> 1 | H6: =IFERROR(VLOOKUP($C6,排班正确!$J:$O,6,FALSE),"/") -> / | I6: =VLOOKUP($C6,缺卡!$H:$K,2,FALSE) -> 6 | J6: =VLOOKUP($C6,缺卡!$H:$K,4,FALSE) -> 0.5 | K6: =VLOOKUP($C6,[2]汇总!$C:$J,5,FALSE) -> 1 | L6: =VLOOKUP($C6,[2]汇总!$C:$J,8,FALSE) -> 0.66666667 | M6: =G6-K6 -> 0 | N6: =J6-L6 -> -0.16666667
A7: FL 佛州大区 | B7: MCO.H | C7: =A7&""&B7 -> FL 佛州大区MCO.H | D7: =VLOOKUP($C7,是否排班!$I:$L,4,FALSE) -> 28 | E7: =VLOOKUP($C7,日超8H!$I:$L,2,FALSE) -> 15 | F7: =VLOOKUP($C7,是否排班!$I:$L,3,FALSE) -> 0 | G7: =VLOOKUP($C7,是否排班!$I:$M,5,FALSE) -> 1 | H7: =IFERROR(VLOOKUP($C7,排班正确!$J:$O,6,FALSE),"/") -> 0.89285714 | I7: =VLOOKUP($C7,缺卡!$H:$K,2,FALSE) -> 5 | J7: =VLOOKUP($C7,缺卡!$H:$K,4,FALSE) -> 0.073529412 | K7: =VLOOKUP($C7,[2]汇总!$C:$J,5,FALSE) -> 1 | L7: =VLOOKUP($C7,[2]汇总!$C:$J,8,FALSE) -> 0.359375 | M7: =G7-K7 -> 0 | N7: =J7-L7 -> -0.28584559
A8: FL 佛州大区 | B8: MCO01 | C8: =A8&""&B8 -> FL 佛州大区MCO01 | D8: =VLOOKUP($C8,是否排班!$I:$L,4,FALSE) -> 2 | E8: =VLOOKUP($C8,日超8H!$I:$L,2,FALSE) -> 2 | F8: =VLOOKUP($C8,是否排班!$I:$L,3,FALSE) -> 0 | G8: =VLOOKUP($C8,是否排班!$I:$M,5,FALSE) -> 1 | H8: =IFERROR(VLOOKUP($C8,排班正确!$J:$O,6,FALSE),"/") -> / | I8: =VLOOKUP($C8,缺卡!$H:$K,2,FALSE) -> 0 | J8: =VLOOKUP($C8,缺卡!$H:$K,4,FALSE) -> 0 | K8: =VLOOKUP($C8,[2]汇总!$C:$J,5,FALSE) -> 1 | L8: =VLOOKUP($C8,[2]汇总!$C:$J,8,FALSE) -> 0 | M8: =G8-K8 -> 0 | N8: =J8-L8 -> 0
A9: FL 佛州大区 | B9: MF 中佛片区 | C9: =A9&""&B9 -> FL 佛州大区MF 中佛片区 | D9: =VLOOKUP($C9,是否排班!$I:$L,4,FALSE) -> 7 | E9: =VLOOKUP($C9,日超8H!$I:$L,2,FALSE) -> 3 | F9: =VLOOKUP($C9,是否排班!$I:$L,3,FALSE) -> 0 | G9: =VLOOKUP($C9,是否排班!$I:$M,5,FALSE) -> 1 | H9: =IFERROR(VLOOKUP($C9,排班正确!$J:$O,6,FALSE),"/") -> / | I9: =VLOOKUP($C9,缺卡!$H:$K,2,FALSE) -> 10 | J9: =VLOOKUP($C9,缺卡!$H:$K,4,FALSE) -> 0.625 | K9: =VLOOKUP($C9,[2]汇总!$C:$J,5,FALSE) -> 0.875 | L9: =VLOOKUP($C9,[2]汇总!$C:$J,8,FALSE) -> 0.57142857 | M9: =G9-K9 -> 0.125 | N9: =J9-L9 -> 0.053571429
A10: FL 佛州大区 | B10: MIA01 | C10: =A10&""&B10 -> FL 佛州大区MIA01 | D10: =VLOOKUP($C10,是否排班!$I:$L,4,FALSE) -> 3 | E10: =VLOOKUP($C10,日超8H!$I:$L,2,FALSE) -> 2 | F10: =VLOOKUP($C10,是否排班!$I:$L,3,FALSE) -> 0 | G10: =VLOOKUP($C10,是否排班!$I:$M,5,FALSE) -> 1 | H10: =IFERROR(VLOOKUP($C10,排班正确!$J:$O,6,FALSE),"/") -> / | I10: =VLOOKUP($C10,缺卡!$H:$K,2,FALSE) -> 1 | J10: =VLOOKUP($C10,缺卡!$H:$K,4,FALSE) -> 0.083333333 | K10: =VLOOKUP($C10,[2]汇总!$C:$J,5,FALSE) -> 1 | L10: =VLOOKUP($C10,[2]汇总!$C:$J,8,FALSE) -> 0 | M10: =G10-K10 -> 0 | N10: =J10-L10 -> 0.083333333
A11: FL 佛州大区 | B11: NF 北佛片区 | C11: =A11&""&B11 -> FL 佛州大区NF 北佛片区 | D11: =VLOOKUP($C11,是否排班!$I:$L,4,FALSE) -> 7 | E11: =VLOOKUP($C11,日超8H!$I:$L,2,FALSE) -> 1 | F11: =VLOOKUP($C11,是否排班!$I:$L,3,FALSE) -> 0 | G11: =VLOOKUP($C11,是否排班!$I:$M,5,FALSE) -> 1 | H11: =IFERROR(VLOOKUP($C11,排班正确!$J:$O,6,FALSE),"/") -> / | I11: =VLOOKUP($C11,缺卡!$H:$K,2,FALSE) -> 6 | J11: =VLOOKUP($C11,缺卡!$H:$K,4,FALSE) -> 0.25 | K11: =VLOOKUP($C11,[2]汇总!$C:$J,5,FALSE) -> 1 | L11: =VLOOKUP($C11,[2]汇总!$C:$J,8,FALSE) -> 0.5 | M11: =G11-K11 -> 0 | N11: =J11-L11 -> -0.25
A12: FL 佛州大区 | B12: OCF01 | C12: =A12&""&B12 -> FL 佛州大区OCF01 | D12: =VLOOKUP($C12,是否排班!$I:$L,4,FALSE) -> 1 | E12: =VLOOKUP($C12,日超8H!$I:$L,2,FALSE) -> 1 | F12: =VLOOKUP($C12,是否排班!$I:$L,3,FALSE) -> 0 | G12: =VLOOKUP($C12,是否排班!$I:$M,5,FALSE) -> 1 | H12: =IFERROR(VLOOKUP($C12,排班正确!$J:$O,6,FALSE),"/") -> / | I12: =VLOOKUP($C12,缺卡!$H:$K,2,FALSE) -> 2 | J12: =VLOOKUP($C12,缺卡!$H:$K,4,FALSE) -> 0.5 | K12: =VLOOKUP($C12,[2]汇总!$C:$J,5,FALSE) -> 1 | L12: =VLOOKUP($C12,[2]汇总!$C:$J,8,FALSE) -> 0.5 | M12: =G12-K12 -> 0 | N12: =J12-L12 -> 0
